Workbook

Sheet E.D
B3: CALCULADORA EVALUACIÓN DE DESEMPEÑO
B5: META | C5: 0.755 | D5: 0.725 | E5: 0.9 | F5: 0.42 | G5: 25 | M5: 0.755 | N5: 0.725 | O5: 0.9 | P5: 0.42 | Q5: 25
B6: PESO | C6: 0.2 | D6: 0.2 | E6: 0.2 | F6: 0.2 | G6: 0.2 | M6: 0.2 | N6: 0.2 | O6: 0.2 | P6: 0.2 | Q6: 0.2
B8: Nombre | C8: Efectividad Fija | D8: Efectividad Movil | E8: Colocaciones | F8: NPS | G8: Ratio Llamadas | H8: Cum. Efec. Hogar | I8: Cum. Efec. Movil | J8: Cum. Retenidos | K8: Cum. NPS | L8: Cum. Ratio | M8: Peso efec Fija | N8: Peso efec movil | O8: Peso colocaciones | P8: Peso NPS | Q8: Peso Ratio Llamadas | R8: Total Peso
B9: A | C9: 0.75 | D9: 0.73 | E9: 0.5 | F9: 0.4 | G9: 24 | H9: =IF(C9>=C5,"100%",C9/C5) -> 0.99337748 | I9: =IF(D9>=D5,"100%",D9/D5) -> 100% | J9: =IF(E9>=E5,"100%",E9/E5) -> 0.55555556 | K9: =IF(F9>=F5,"100%",F9/F5) -> 0.95238095 | L9: =IF(G9>=G5,"100%",G9/G5) -> 0.96 | M9: =H9*M6 -> 0.1986755 | N9: =I9*N6 -> 0.2 | O9: =J9*O6 -> 0.11111111 | P9: =K9*P6 -> 0.19047619 | Q9: =L9*Q6 -> 0.192 | R9: =SUM(M9:Q9) -> 0.8922628
B13: CALCULADORA NPS
B15: PROMOTORES | C15: DETRACTORES | D15: NEUTROS | E15: ENCUESTAS | F15: %NPS | H15: %PROMOTORES | I15: %DETRACTORES
B16: 5 | C16: 2 | D16: 0 | E16: =SUM(B16:D16) -> 7 | F16: =H16-I16 -> 0.42857143 | H16: =B16/E16 -> 0.71428571 | I16: =C16/E16 -> 0.28571429
B20: OBSERVACIONES: • El seguimiento de los indicadores es un compromiso del grupo de trabajo, Colaboradores_x0002_Supervisores-Jefatura, motivo por el cual se trabajará con un modelo de Feedback que busca potencializar las habilidades de los colaboradores y el cumplimiento de los indicadores con el incentivo de las comisiones, como parte del proceso de seguimiento aceptamos las normatividades para el cumplimiento de estos: • La Evaluación de desempeño es un proceso de seguimiento y Feedback la calificación inferior al 95% debe ser asegurada con un recordatorio de funciones con el compromiso del colaborador, la reincidencia en 3 evaluaciones se remite al área de jurídica para realizar el proceso correspondiente. • Los colaboradores son conscientes del tiempo reglamentario de las jornadas de trabajo y reconocen que los auxiliares no autorizados o excesos de estos al igual que retardos e inasistencias perjudican la labor contratada no permiten el cumplimiento de los indicadores y las comisiones.

Sheet PTAR
C2: RECUERDE CAMBIAR EL NÚMERO FINAL DEL CÓDIGO SEGÚN EL ESTRATO DEL CLIENTE | G2: RECUERDE CAMBIAR EL NÚMERO FINAL DEL CÓDIGO SEGÚN EL ESTRATO DEL CLIENTE
B4: PTAR | F4: PTAR | J4: PTAR
B5: 1008 | F5: 1010 | J5: 1005
B6: TARIFAS TRIPLES CLARO | C6: ESTRATO 1 | D6: CODIGO | F6: TARIFAS TRIPLES CLARO | G6: ESTRATO 1 | H6: CODIGO | J6: No Todo Claro
B7: Triple Digital Superior 500 MB (1) (5) (6) (7) | C7: 136900 | D7: CDP1 | F7: Triple Digital Superior 900 MB (1) (5) (6) (7) | G7: 136900 | H7: CED1 | J7: TV SATELITAL | Q7: TV SATELITAL AVANZADA | U7: TV SATELITAL SUPERIOR
B8: Triple Digital Superior 500 MB (2) (5) (6) (7) | C8: 136900 | D8: CDR1 | F8: Triple Digital Superior 900 MB (2) (5) (6) (7) | G8: 136900 | H8: CEE1 | J8: NACIONAL | M8: Leticia | O8: Puerto Carreño, Quibdó, Inirida y Mitú | Q8: NACIONAL | S8: Leticia | U8: NACIONAL | W8: Leticia
B9: Triple Digital Superior 500 MB (3) (5) (6) (7) | C9: 136900 | D9: CDW1 | F9: Triple Digital Superior 900 MB (3) (5) (6) (7) | G9: 136900 | H9: CEG1 | J9: Estrato | K9: Codigo | L9: valor | M9: Codigo | N9: valor | O9: Codigo | P9: valor | Q9: Codigo | R9: valor | S9: Codigo | T9: valor | U9: Codigo | V9: valor | W9: Codigo | X9: valor
B10: Triple Digital Superior 500 MB (4) (5) (6) (7) | C10: 136900 | D10: CDT1 | F10: Triple Digital Superior 900 MB (4) (5) (6) (7) | G10: 136900 | H10: CEF1 | J10: 1 | K10: LKO1 | L10: 63900 | M10: LKR1 | N10: 54900 | O10: LKQ1 | P10: 65900 | Q10: LKM1 | R10: 73900 | S10: LKN1 | T10: 62900 | U10: LKK1 | V10: 81900 | W10: LKL1 | X10: 69900
B11: Triple Digital Avanzada 500 MB (1) (5) (6) (7) | C11: 121900 | D11: CDE1 | F11: Triple Digital Avanzada 900 MB (1) (5) (6) (7) | G11: 121900 | H11: CDY1 | J11: 2 | K11: LKO2 | L11: 63900 | M11: LKR2 | N11: 54900 | O11: LKQ2 | P11: 65900 | Q11: LKM2 | R11: 73900 | S11: LKN2 | T11: 62900 | U11: LKK2 | V11: 81900 | W11: LKL2 | X11: 69900
B12: Triple Digital Avanzada 500 MB (2) (5) (6) (7) | C12: 121900 | D12: CDF1 | F12: Triple Digital Avanzada 900 MB (2) (5) (6) (7) | G12: 121900 | H12: CDZ1 | J12: 3 | K12: LKO3 | L12: 63900 | M12: LKR3 | N12: 54900 | O12: LKQ3 | P12: 65900 | Q12: LKM3 | R12: 73900 | S12: LKN3 | T12: 62900 | U12: LKK3 | V12: 81900 | W12: LKL3 | X12: 69900
B13: Triple Digital Avanzada 500 MB (3) (5) (6) (7) | C13: 121900 | D13: CDN1 | F13: Triple Digital Avanzada 900 MB (3) (5) (6) (7) | G13: 121900 | H13: CEC1 | J13: 4 | K13: LKO4 | L13: 63900 | M13: LKR4 | N13: 54900 | O13: LKQ4 | P13: 65900 | Q13: LKM4 | R13: 73900 | S13: LKN4 | T13: 62900 | U13: LKK4 | V13: 81900 | W13: LKL4 | X13: 69900
B14: Triple Digital Avanzada 500 MB (4) (5) (6) (7) | C14: 121900 | D14: CDJ1 | F14: Triple Digital Avanzada 900 MB (4) (5) (6) (7) | G14: 121900 | H14: CEB1 | J14: 5 | K14: LKO5 | L14: 63900 | M14: LKR5 | N14: 54900 | O14: LKQ5 | P14: 65900 | Q14: LKM5 | R14: 73900 | S14: LKN5 | T14: 62900 | U14: LKK5 | V14: 81900 | W14: LKL5 | X14: 69900
B15: Triple Box TV Digital Intermedio Plus 600 MB (1) (2) (7) (8) +UW | C15: 116900 | D15: U031 | F15: Triple Box TV Digital Intermedio Plus 900 MB (1) (2) (7) (8) | G15: 116900 | H15: U001 | J15: 6 | K15: LKO6 | L15: 63900 | M15: LKR6 | N15: 54900 | O15: LKQ6 | P15: 65900 | Q15: LKM6 | R15: 73900 | S15: LKN6 | T15: 62900 | U15: LKK6 | V15: 81900 | W15: LKL6 | X15: 69900
B16: Triple Box TV Digital Intermedio Plus 600 MB (1) (3) (7) (8) +UW | C16: 116900 | D16: U041 | F16: Triple Box TV Digital Intermedio Plus 900 MB (1) (3) (7) (8) | G16: 116900 | H16: U011
B17: Triple Box TV Digital Intermedio Plus 600 MB (3) (4) (7) (8) +UW | C17: 116900 | D17: U051 | F17: Triple Box TV Digital Intermedio Plus 900 MB (3) (4) (7) (8) | G17: 116900 | H17: U021 | J17: Todo claro
B18: Triple Claro TV+ Intermedio Plus 500 MB (1) (2) (5) (6) | C18: 111900 | D18: BZZ1 | F18: Triple Claro TV+ Intermedio Plus 900 MB (1) (2) (5) (6) | G18: 111900 | H18: BYU1 | J18: TV SATELITAL AVANZADO | Q18: TV SATELITAL SUPERIOR
B19: Triple Claro TV+ Intermedio Plus 500 MB (1) (3) (5) (6) | C19: 111900 | D19: CBG1 | F19: Triple Claro TV+ Intermedio Plus 900 MB (1) (3) (5) (6) | G19: 111900 | H19: BYV1 | J19: NACIONAL | M19: Leticia | O19: Puerto Carreño, Quibdó, Inirida y Mitú | Q19: NACIONAL | S19: Leticia
B20: Triple Claro TV+ Intermedio Plus 500 MB (3) (4) (5) (6) | C20: 111900 | D20: CBI1 | F20: Triple Claro TV+ Intermedio Plus 900 MB (3) (4) (5) (6) | G20: 111900 | H20: BYW1 | J20: Estrato | K20: Codigo | L20: valor | M20: Codigo | N20: valor | O20: Codigo | P20: valor | Q20: Codigo | R20: valor | S20: Codigo | T20: valor
B21: Triple Digital Intermedio Plus 500 MB (1) (5) (7) | C21: 109900 | D21: CBQ1 | F21: Triple Digital Intermedio Plus 900 MB (1) (5) (7) | G21: 109900 | H21: BZG1 | J21: 1 | K21: LK31 | L21: 63900 | M21: LK41 | N21: 54900 | O21: LK51 | P21: 65900 | Q21: LK11 | R21: 73900 | S21: LK21 | T21: 62900
B22: Triple Digital Intermedio Plus 500 MB (2) (5) (7) | C22: 109900 | D22: CBU1 | F22: Triple Digital Intermedio Plus 900 MB (2) (5) (7) | G22: 109900 | H22: BZL1 | J22: 2 | K22: LK32 | L22: 63900 | M22: LK42 | N22: 54900 | O22: LK52 | P22: 65900 | Q22: LK12 | R22: 73900 | S22: LK22 | T22: 62900
B23: Triple Digital Intermedio Plus 500 MB (3) (5) (7) | C23: 109900 | D23: CBZ1 | F23: Triple Digital Intermedio Plus 900 MB (3) (5) (7) | G23: 109900 | H23: BZP1 | J23: 3 | K23: LK33 | L23: 63900 | M23: LK43 | N23: 54900 | O23: LK53 | P23: 65900 | Q23: LK13 | R23: 73900 | S23: LK23 | T23: 62900
B24: Triple Digital Intermedio Plus 500 MB (4) (5) (7) | C24: 109900 | D24: CBS1 | F24: Triple Digital Intermedio Plus 900 MB (4) (5) (7) | G24: 109900 | H24: BZJ1 | J24: 4 | K24: LK34 | L24: 63900 | M24: LK44 | N24: 54900 | O24: LK54 | P24: 65900 | Q24: LK14 | R24: 73900 | S24: LK24 | T24: 62900
B25: Triple Digital Intermedio Plus 500 MB (1) (6) (7) | C25: 104900 | D25: CBP1 | F25: Triple Digital Intermedio Plus 900 MB (1) (6) (7) | G25: 104900 | H25: BZF1 | J25: 5 | K25: LK35 | L25: 63900 | M25: LK45 | N25: 54900 | O25: LK55 | P25: 65900 | Q25: LK15 | R25: 73900 | S25: LK25 | T25: 62900
B26: Triple Digital Intermedio Plus 500 MB (1) (7) | C26: 99900 | D26: CBO1 | F26: Triple Digital Intermedio Plus 900 MB (1) (7) | G26: 99900 | H26: BZE1 | J26: 6 | K26: LK36 | L26: 63900 | M26: LK46 | N26: 54900 | O26: LK56 | P26: 65900 | Q26: LK16 | R26: 73900 | S26: LK26 | T26: 62900
B27: Triple Digital Intermedio Plus 500 MB (2) (7) | C27: 99900 | D27: CBT1 | F27: Triple Digital Intermedio Plus 900 MB (2) (7) | G27: 99900 | H27: BZK1
B28: Triple Digital Intermedio Plus 500 MB (3) (7) | C28: 99900 | D28: CBW1 | F28: Triple Digital Intermedio Plus 900 MB (3) (7) | G28: 99900 | H28: BZO1
B29: Triple Digital Intermedio Plus 500 MB (4) (7) | C29: 99900 | D29: CBR1 | F29: Triple Digital Intermedio Plus 900 MB (4) (7) | G29: 99900 | H29: BZH1
B30: Triple Digital Intermedio Plus 500 MB (5) (7) | C30: 99900 | D30: CBN1 | F30: Triple Digital Intermedio Plus 900 MB (5) (7) | G30: 99900 | H30: BZD1
B31: Triple Claro TV+ Básica 500 MB | C31: 79900 | D31: CA61 | F31: Triple Claro TV+ Básico 900 MB | G31: 79900 | H31: CA71
B33: TARIFA DOBLE CLARO | C33: ESTRATO 1 | D33: COD_TAR_RE | F33: TARIFA DOBLE CLARO | G33: ESTRATO 1 | H33: COD_TAR_RE
B34: Internet 500 MB + Voz | C34: 79900 | D34: N/A | F34: Internet 900 MB + Voz | G34: 79900 | H34: N/A
B37: TARIFAS SENCILLOS | C37: ESTRATO 1 | D37: COD_TAR_RE | F37: TARIFAS SENCILLOS | G37: ESTRATO 1 | H37: COD_TAR_RE
B38: Tv Digital Superior | C38: $ 85.900 | D38: KSF1 | F38: Internet 900 MB | G38: 74900 | H38: BZY1
B39: Tv Digital Avanzada | C39: $ 73.900 | D39: KSG1 | F39: Telefonía | G39: 52900 | H39: WNG1
B40: Tv Digital Intermedio Plus | C40: $ 63.900 | D40: K051
B41: Internet 500 MB | C41: $ 74.900 | D41: CCT1
B42: Telefonía | C42: $ 52.900 | D42: BMM1

Sheet GENERAL
B2: LLAMADAS | C2: RETENIDOS HOGAR | D2: CANCELADOS HOGAR | E2: RETENIDOS MOVIL | F2: CANCELADOS MOVIL | G2: INF_NIA | H2: IDENTIDA | I2: GES_NCC | J2: MAL TRANSFERIDAS | K2: LLAMADA CAIDA | L2: TOTAL RETENIDOS | M2: TOTAL CANCELADOS
B3: =SUM('01-09'!H5,'02-09'!H5,'03-09'!H5,'04-09'!H5,'05-09'!H5,'06-09'!H5,'08-09'!H5,'09-09'!H5,'10-09'!H5,'11-09'!H5,'12-09'!H5,'13-09'!H5,'15-09'!H5,'16-09'!H5,'17-09'!H5,'18-09'!H5,'19-09'!H5,'20-09'!H5,'22-09'!H5,'23-09'!H5,'24-09'!H5,'25-09'!H5,'26-09'!H5,'27-09'!H5,'29-09'!H5,'30-09'!H5) -> 1 | C3: =SUM('01-09'!I5,'02-09'!I5,'03-09'!I5,'04-09'!I5,'05-09'!I5,'06-09'!I5,'08-09'!I5,'09-09'!I5,'10-09'!I5,'11-09'!I5,'12-09'!I5,'13-09'!I5,'15-09'!I5,'16-09'!I5,'17-09'!I5,'18-09'!I5,'19-09'!I5,'20-09'!I5,'22-09'!I5,'23-09'!I5,'24-09'!I5,'25-09'!I5,'26-09'!I5,'27-09'!I5,'29-09'!I5,'30-09'!I5) -> 1 | D3: =SUM('01-09'!J5,'02-09'!J5,'03-09'!J5,'04-09'!J5,'05-09'!J5,'06-09'!J5,'08-09'!J5,'09-09'!J5,'10-09'!J5,'11-09'!J5,'12-09'!J5,'13-09'!J5,'15-09'!J5,'16-09'!J5,'17-09'!J5,'18-09'!J5,'19-09'!J5,'20-09'!J5,'22-09'!J5,'23-09'!J5,'24-09'!J5,'25-09'!J5,'26-09'!J5,'27-09'!J5,'29-09'!J5,'30-09'!J5) -> 0 | E3: =SUM('01-09'!K5,'02-09'!K5,'03-09'!K5,'04-09'!K5,'05-09'!K5,'06-09'!K5,'08-09'!K5,'09-09'!K5,'10-09'!K5,'11-09'!K5,'12-09'!K5,'13-09'!K5,'15-09'!K5,'16-09'!K5,'17-09'!K5,'18-09'!K5,'19-09'!K5,'20-09'!K5,'22-09'!K5,'23-09'!K5,'24-09'!K5,'25-09'!K5,'26-09'!K5,'27-09'!K5,'29-09'!K5,'30-09'!K5) -> 0 | F3: =SUM('01-09'!L5,'02-09'!L5,'03-09'!L5,'04-09'!L5,'05-09'!L5,'06-09'!L5,'08-09'!L5,'09-09'!L5,'10-09'!L5,'11-09'!L5,'12-09'!L5,'13-09'!L5,'15-09'!L5,'16-09'!L5,'17-09'!L5,'18-09'!L5,'19-09'!L5,'20-09'!L5,'22-09'!L5,'23-09'!L5,'24-09'!L5,'25-09'!L5,'26-09'!L5,'27-09'!L5,'29-09'!L5,'30-09'!L5) -> 0 | G3: =SUM('01-09'!M5,'02-09'!M5,'03-09'!M5,'04-09'!M5,'05-09'!M5,'06-09'!M5,'08-09'!M5,'09-09'!M5,'10-09'!M5,'11-09'!M5,'12-09'!M5,'13-09'!M5,'15-09'!M5,'16-09'!M5,'17-09'!M5,'18-09'!M5,'19-09'!M5,'20-09'!M5,'22-09'!M5,'23-09'!M5,'24-09'!M5,'25-09'!M5,'26-09'!M5,'27-09'!M5,'29-09'!M5,'30-09'!M5) -> 0 | H3: =SUM('01-09'!N5,'02-09'!N5,'03-09'!N5,'04-09'!N5,'05-09'!N5,'06-09'!N5,'08-09'!N5,'09-09'!N5,'10-09'!N5,'11-09'!N5,'12-09'!N5,'13-09'!N5,'15-09'!N5,'16-09'!N5,'17-09'!N5,'18-09'!N5,'19-09'!N5,'20-09'!N5,'22-09'!N5,'23-09'!N5,'24-09'!N5,'25-09'!N5,'26-09'!N5,'27-09'!N5,'29-09'!N5,'30-09'!N5) -> 0 | I3: =SUM('01-09'!O5,'02-09'!O5,'03-09'!O5,'04-09'!O5,'05-09'!O5,'06-09'!O5,'08-09'!O5,'09-09'!O5,'10-09'!O5,'11-09'!O5,'12-09'!O5,'13-09'!O5,'15-09'!O5,'16-09'!O5,'17-09'!O5,'18-09'!O5,'19-09'!O5,'20-09'!O5,'22-09'!O5,'23-09'!O5,'24-09'!O5,'25-09'!O5,'26-09'!O5,'27-09'!O5,'29-09'!O5,'30-09'!O5) -> 0 | ... K3: =SUM('01-09'!Q5,'02-09'!Q5,'03-09'!Q5,'04-09'!Q5,'05-09'!Q5,'06-09'!Q5,'08-09'!Q5,'09-09'!Q5,'10-09'!Q5,'11-09'!Q5,'12-09'!Q5,'13-09'!Q5,'15-09'!Q5,'16-09'!Q5,'17-09'!Q5,'18-09'!Q5,'19-09'!Q5,'20-09'!Q5,'22-09'!Q5,'23-09'!Q5,'24-09'!Q5,'25-09'!Q5,'26-09'!Q5,'27-09'!Q5,'29-09'!Q5,'30-09'!Q5) -> 0 | L3: =SUM(C3,E3) -> 1 | M3: =SUM(D3,F3) -> 0
B6: EFECTIVIDAD EN INTENCIONES HOGAR | E6: EFECTIVIDAD EN INTENCIONES MOVIL | H6: % COLOCACIONES | K6: EFECTIVIDAD MENSUAL GENERAL
B7: =IFERROR(C3/SUM(C3:D3),"-") -> 1 | E7: =IFERROR(E3/SUM(E3:F3),"-") -> - | H7: {=IFERROR(SUM(C3:I3/B3),"-")} -> 1 | K7: =IFERROR(L3/SUM(L3:M3),"-") -> 1
E9: META | F9: 102 | G9: 102 | H9: 102 | I9: 136
E10: SERVICIOS RETENIDOS MES | F10: SEMANA 1 | G10: SEMANA 2 | H10: SEMANA 3 | I10: SEMANA 4
E11: =SUM('01-09'!J18:M19,'02-09'!J18:M19,'03-09'!J18:M19,'04-09'!J18:M19,'05-09'!J18:M19,'06-09'!J18:M19,'08-09'!J18:M19,'09-09'!J18:M19,'10-09'!J18:M19,'11-09'!J18:M19,'12-09'!J18:M19,'13-09'!J18:M19,'15-09'!J18:M19,'16-09'!J18:M19,'17-09'!J18:M19,'18-09'!J18:M19,'19-09'!J18:M19,'20-09'!J18:M19,'22-09'!J18:M19,'23-09'!J18:M19,'24-09'!J18:M19,'25-09'!J18:M19,'26-09'!J18:M19,'27-09'!J18:M19,'29-09'!J18:M19,'30-09'!J18:M19) -> 3 | F11: =SUM('01-09'!J18:M19,'02-09'!J18:M19,'03-09'!J18:M19,'04-09'!J18:M19,'05-09'!J18:M19,'06-09'!J18:M19) -> 3 | G11: =SUM('08-09'!J18:M19,'09-09'!J18:M19,'10-09'!J18:M19,'11-09'!J18:M19,'12-09'!J18:M19,'13-09'!J18:M19) -> 0 | H11: =SUM('15-09'!J18:M19,'16-09'!J18:M19,'17-09'!J18:M19,'18-09'!J18:M19,'19-09'!J18:M19,'20-09'!J18:M19) -> 0 | I11: =SUM('22-09'!J18:M19,'23-09'!J18:M19,'24-09'!J18:M19,'25-09'!J18:M19,'26-09'!J18:M19,'27-09'!J18:M19,'29-09'!J18:M19,'30-09'!J18:M19) -> 0
E13: COMISIÓN PARCIAL
E14: =SUM('01-09'!I25:Q29,'02-09'!I25:Q29,'03-09'!I25:Q29,'04-09'!I25:Q29,'05-09'!I25:Q29,'06-09'!I25:Q29,'08-09'!I25:Q29,'09-09'!I25:Q29,'10-09'!I25:Q29,'11-09'!I25:Q29,'12-09'!I25:Q29,'13-09'!I25:Q29,'15-09'!I25:Q29,'16-09'!I25:Q29,'17-09'!I25:Q29,'18-09'!I25:Q29,'19-09'!I25:Q29,'20-09'!I25:Q29,'22-09'!I25:Q29,'23-09'!I25:Q29,'24-09'!I25:Q29,'25-09'!I25:Q29,'26-09'!I25:Q29,'27-09'!I25:Q29,'29-09'!I25:Q29,'30-09'!I25:Q29) -> 0
E16: MODELO DE COMISIÓN
B28: ¡¡¡ IMPORTANTE !!!
B30: SI FALTA ALGÚN DÍA DEBE HACER MÍNIMO 102 SERVICIOS RETENIDOS EN LA SEMANA PARA QUE SE PAGUEN LOS RETENIDOS
B31: TODAS LAS CUENTAS DEBEN ESTAR TIPIFICADAS EN SOUL Y DIME DE LO CONTRARIO NO SE PAGARÁN LOS RETENIDOS
B32: SE PENALIZARÁ EL 10% DE SU COMISIÓN FINAL SI CALIDAD NO ESTÁ POR ENCIMA DEL 70%
B33: SE PENALIZARÁ EL 20% DE SU COMISIÓN FINAL SI NO CUMPLE CON LA META DEL NPS
B34: SI LA COLOCACIÓN FINAL ESTÁ POR DEBAJO DEL 90% LAS LLAMADAS FALTANTES SE SUMARÁN A LOS NO RETENIDOS
B35: SI NO ALCANZA LA META DIARIA DE RETENIDOS PERO SI LA META SEMANAL QUE SON MÍNIMO 102 SE LE PAGAN TODOS LOS RETENIDOS DE LA SEMANA

Sheet 01-09
B2: MENÚ PRINCIPAL | C2: RETENCIÓN | E2: EFECTIVIDAD HOGAR | G2: =GENERAL!B7 -> 1 | I2: EFECTIVIDAD MOVIL | K2: =GENERAL!E7 -> - | M2: EFECTIVIDAD MENSUAL | O2: =GENERAL!K7 -> 1
B4: NÚMERO/ CUENTA | C4: OBSERVACIÓN | D4: GESTIÓN | E4: SERVICIOS RETENIDOS | F4: SERVICIOS CANCELADOS | H4: LLAMADAS | I4: RETENIDOS HOGAR | J4: CAN HOGAR | K4: RETENIDOS MOVIL | L4: CAN MOVIL | M4: INF_NIA | N4: IDENTIDA | O4: GES_NCC | P4: MAL TRANSFER | Q4: LLAMADA CAIDA | T4: RETE | U4: EFEC | V4: EFEC | W4: EFEC | Y4: LISTA | Z4: SERVICIOS | AA4: SERVICIOS
B5: 3333 | C5: Radicado soul | D5: RETENIDO HOGAR | E5: 3 | H5: =COUNT(B5:B50) -> 1 | I5: =COUNTIF($D$5:$D$50,"RETENIDO HOGAR") -> 1 | J5: =COUNTIF($D$5:$D$50,"CANCELADO HOGAR") -> 0 | K5: =COUNTIF($D$5:$D$50,"RETENIDO MOVIL") -> 0 | L5: =COUNTIF($D$5:$D$50,"CANCELADO MOVIL") -> 0 | M5: =COUNTIF(D5:D50,"INF_NIA") -> 0 | N5: =COUNTIF(D5:D50,"IDENTIDA") -> 0 | O5: =COUNTIF(D5:D50,"GES_NCC") -> 0 | P5: =COUNTIF($D$5:$D$50,"MAL TRANSFERIDA") -> 0 | Q5: =COUNTIF($D$5:$D$50,"LLAMADA CAIDA") -> 0 | U5: 0.74 | V5: 0.76 | W5: 0.78 | Y5: RETENIDO HOGAR | Z5: 1 | AA5: 1
T6: 17 | U6: 2300 | V6: 2600 | W6: 2900 | Y6: CANCELADO HOGAR | Z6: 2
T7: 19 | U7: 2700 | V7: 3000 | W7: 3300 | Y7: RETENIDO MOVIL | Z7: 3
H8: EFECTIVIDAD DIA HOGAR | K8: EFECTIVIDAD DIA MOVIL | N8: %MARCACIONES | P8: EFECTIVIDAD DIA GENERAL | T8: 21 | U8: 3000 | V8: 3300 | W8: 3600 | Y8: CANCELADO MOVIL
T9: 23 | U9: 3300 | V9: 3600 | W9: 3900 | Y9: INF_NIA
Y10: IDENTIDA
H11: =IFERROR(I5/SUM(I5:J5),"-") -> 1 | K11: =IFERROR(K5/SUM(K5:L5),"-") -> - | N11: {=IFERROR(SUM(I5:O5/H5),"-")} -> 1 | P11: =IFERROR(SUM(I5,K5)/SUM(I5:L5),"-") -> 1 | Y11: GES_NCC
Y12: MAL TRANSFERIDA
Y13: LLAMADA CAIDA
J15: SERVICIOS RETENIDOS | N15: SERVICIOS CANCELADOS
J18: =IFERROR(SUM($E$5:$E$50),"-") -> 3 | N18: =SUM(F5:F50) -> 0
I21: COMISIÓN DEL DÍA
I25: =IF(AND(J18>=T9,O2>=W5),J18*W9,IF(AND(J18>=T8,J18<T9,O2>=W5),J18*W8,IF(AND(J18>=T7,J18<T8,O2>=W5),J18*W7,IF(AND(J18>=T6,J18<T7,O2>=W5),J18*W6,IF(AND(J18>=T9,O2>=V5,O2<W5),J18*V9,IF(AND(J18>=T9,O2>=V5,O2<W5),J18*V8,IF(AND(J18>=T7,J18<T8,O2>=V5,O2<W5),J18*V7,IF(AND(J18>=T6,J18<T7,O2>=V5,O2<W5),J18*V6,IF(AND(J18>=T9,O2>=U5,O2<V5),J18*U9,IF(AND(J18>=T8,J18<T9,O2>=U5,O2<V5),J18*U8,IF(AND(J18>=T7,J18<T8,O2>=U5,O2<V5),J18*U7,IF(AND(J18>=T6,J18<T7,O2>=U5,O2<V5),J18*U6,"MUY SUAVE EN RETENIDOS 🥱")))))))))))) -> MUY SUAVE EN RETENIDOS 🥱

Sheet 02-09
B2: MENÚ PRINCIPAL | C2: RETENCIÓN | E2: EFECTIVIDAD HOGAR | G2: =GENERAL!B7 -> 1 | I2: EFECTIVIDAD MOVIL | K2: =GENERAL!E7 -> - | M2: EFECTIVIDAD MENSUAL | O2: =GENERAL!K7 -> 1
B4: NÚMERO/ CUENTA | C4: OBSERVACIÓN | D4: GESTIÓN | E4: SERVICIOS RETENIDOS | F4: SERVICIOS CANCELADOS | H4: LLAMADAS | I4: RETENIDOS HOGAR | J4: CAN HOGAR | K4: RETENIDOS MOVIL | L4: CAN MOVIL | M4: INF_NIA | N4: IDENTIDA | O4: GES_NCC | P4: MAL TRANSFER | Q4: LLAMADA CAIDA | T4: RETE | U4: EFEC | V4: EFEC | W4: EFEC | Y4: LISTA | Z4: SERVICIOS | AA4: SERVICIOS
H5: =COUNT(B5:B50) -> 0 | I5: =COUNTIF($D$5:$D$50,"RETENIDO HOGAR") -> 0 | J5: =COUNTIF($D$5:$D$50,"CANCELADO HOGAR") -> 0 | K5: =COUNTIF($D$5:$D$50,"RETENIDO MOVIL") -> 0 | L5: =COUNTIF($D$5:$D$50,"CANCELADO MOVIL") -> 0 | M5: =COUNTIF(D5:D50,"INF_NIA") -> 0 | N5: =COUNTIF(D5:D50,"IDENTIDA") -> 0 | O5: =COUNTIF(D5:D50,"GES_NCC") -> 0 | P5: =COUNTIF($D$5:$D$50,"MAL TRANSFERIDA") -> 0 | Q5: =COUNTIF($D$5:$D$50,"LLAMADA CAIDA") -> 0 | U5: 0.74 | V5: 0.76 | W5: 0.78 | Y5: RETENIDO HOGAR | Z5: 1 | AA5: 1
T6: 17 | U6: 2300 | V6: 2600 | W6: 2900 | Y6: CANCELADO HOGAR | Z6: 2
T7: 19 | U7: 2700 | V7: 3000 | W7: 3300 | Y7: RETENIDO MOVIL | Z7: 3
H8: EFECTIVIDAD DIA HOGAR | K8: EFECTIVIDAD DIA MOVIL | N8: %MARCACIONES | P8: EFECTIVIDAD DIA GENERAL | T8: 21 | U8: 3000 | V8: 3300 | W8: 3600 | Y8: CANCELADO MOVIL
T9: 23 | U9: 3300 | V9: 3600 | W9: 3900 | Y9: INF_NIA
Y10: IDENTIDA
H11: =IFERROR(I5/SUM(I5:J5),"-") -> - | K11: =IFERROR(K5/SUM(K5:L5),"-") -> - | N11: {=IFERROR(SUM(I5:O5/H5),"-")} -> - | P11: =IFERROR(SUM(I5,K5)/SUM(I5:L5),"-") -> - | Y11: GES_NCC
Y12: MAL TRANSFERIDA
Y13: LLAMADA CAIDA
J15: SERVICIOS RETENIDOS | N15: SERVICIOS CANCELADOS
J18: =IFERROR(SUM($E$5:$E$50),"-") -> 0 | N18: =SUM(F5:F50) -> 0
I21: COMISIÓN DEL DÍA
I25: =IF(AND(J18>=T9,O2>=W5),J18*W9,IF(AND(J18>=T8,J18<T9,O2>=W5),J18*W8,IF(AND(J18>=T7,J18<T8,O2>=W5),J18*W7,IF(AND(J18>=T6,J18<T7,O2>=W5),J18*W6,IF(AND(J18>=T9,O2>=V5,O2<W5),J18*V9,IF(AND(J18>=T9,O2>=V5,O2<W5),J18*V8,IF(AND(J18>=T7,J18<T8,O2>=V5,O2<W5),J18*V7,IF(AND(J18>=T6,J18<T7,O2>=V5,O2<W5),J18*V6,IF(AND(J18>=T9,O2>=U5,O2<V5),J18*U9,IF(AND(J18>=T8,J18<T9,O2>=U5,O2<V5),J18*U8,IF(AND(J18>=T7,J18<T8,O2>=U5,O2<V5),J18*U7,IF(AND(J18>=T6,J18<T7,O2>=U5,O2<V5),J18*U6,"MUY SUAVE EN RETENIDOS 🥱")))))))))))) -> MUY SUAVE EN RETENIDOS 🥱

Sheet 03-09
B2: MENÚ PRINCIPAL | C2: RETENCIÓN | E2: EFECTIVIDAD HOGAR | G2: =GENERAL!B7 -> 1 | I2: EFECTIVIDAD MOVIL | K2: =GENERAL!E7 -> - | M2: EFECTIVIDAD MENSUAL | O2: =GENERAL!K7 -> 1
B4: NÚMERO/ CUENTA | C4: OBSERVACIÓN | D4: GESTIÓN | E4: SERVICIOS RETENIDOS | F4: SERVICIOS CANCELADOS | H4: LLAMADAS | I4: RETENIDOS HOGAR | J4: CAN HOGAR | K4: RETENIDOS MOVIL | L4: CAN MOVIL | M4: INF_NIA | N4: IDENTIDA | O4: GES_NCC | P4: MAL TRANSFER | Q4: LLAMADA CAIDA | T4: RETE | U4: EFEC | V4: EFEC | W4: EFEC | Y4: LISTA | Z4: SERVICIOS | AA4: SERVICIOS
H5: =COUNT(B5:B50) -> 0 | I5: =COUNTIF($D$5:$D$50,"RETENIDO HOGAR") -> 0 | J5: =COUNTIF($D$5:$D$50,"CANCELADO HOGAR") -> 0 | K5: =COUNTIF($D$5:$D$50,"RETENIDO MOVIL") -> 0 | L5: =COUNTIF($D$5:$D$50,"CANCELADO MOVIL") -> 0 | M5: =COUNTIF(D5:D50,"INF_NIA") -> 0 | N5: =COUNTIF(D5:D50,"IDENTIDA") -> 0 | O5: =COUNTIF(D5:D50,"GES_NCC") -> 0 | P5: =COUNTIF($D$5:$D$50,"MAL TRANSFERIDA") -> 0 | Q5: =COUNTIF($D$5:$D$50,"LLAMADA CAIDA") -> 0 | U5: 0.74 | V5: 0.76 | W5: 0.78 | Y5: RETENIDO HOGAR | Z5: 1 | AA5: 1
T6: 17 | U6: 2300 | V6: 2600 | W6: 2900 | Y6: CANCELADO HOGAR | Z6: 2
T7: 19 | U7: 2700 | V7: 3000 | W7: 3300 | Y7: RETENIDO MOVIL | Z7: 3
H8: EFECTIVIDAD DIA HOGAR | K8: EFECTIVIDAD DIA MOVIL | N8: %MARCACIONES | P8: EFECTIVIDAD DIA GENERAL | T8: 21 | U8: 3000 | V8: 3300 | W8: 3600 | Y8: CANCELADO MOVIL
T9: 23 | U9: 3300 | V9: 3600 | W9: 3900 | Y9: INF_NIA
Y10: IDENTIDA
H11: =IFERROR(I5/SUM(I5:J5),"-") -> - | K11: =IFERROR(K5/SUM(K5:L5),"-") -> - | N11: {=IFERROR(SUM(I5:O5/H5),"-")} -> - | P11: =IFERROR(SUM(I5,K5)/SUM(I5:L5),"-") -> - | Y11: GES_NCC
Y12: MAL TRANSFERIDA
Y13: LLAMADA CAIDA
J15: SERVICIOS RETENIDOS | N15: SERVICIOS CANCELADOS
J18: =IFERROR(SUM($E$5:$E$50),"-") -> 0 | N18: =SUM(F5:F50) -> 0
I21: COMISIÓN DEL DÍA
I25: =IF(AND(J18>=T9,O2>=W5),J18*W9,IF(AND(J18>=T8,J18<T9,O2>=W5),J18*W8,IF(AND(J18>=T7,J18<T8,O2>=W5),J18*W7,IF(AND(J18>=T6,J18<T7,O2>=W5),J18*W6,IF(AND(J18>=T9,O2>=V5,O2<W5),J18*V9,IF(AND(J18>=T9,O2>=V5,O2<W5),J18*V8,IF(AND(J18>=T7,J18<T8,O2>=V5,O2<W5),J18*V7,IF(AND(J18>=T6,J18<T7,O2>=V5,O2<W5),J18*V6,IF(AND(J18>=T9,O2>=U5,O2<V5),J18*U9,IF(AND(J18>=T8,J18<T9,O2>=U5,O2<V5),J18*U8,IF(AND(J18>=T7,J18<T8,O2>=U5,O2<V5),J18*U7,IF(AND(J18>=T6,J18<T7,O2>=U5,O2<V5),J18*U6,"MUY SUAVE EN RETENIDOS 🥱")))))))))))) -> MUY SUAVE EN RETENIDOS 🥱

Sheet 04-09
B2: MENÚ PRINCIPAL | C2: RETENCIÓN | E2: EFECTIVIDAD HOGAR | G2: =GENERAL!B7 -> 1 | I2: EFECTIVIDAD MOVIL | K2: =GENERAL!E7 -> - | M2: EFECTIVIDAD MENSUAL | O2: =GENERAL!K7 -> 1
B4: NÚMERO/ CUENTA | C4: OBSERVACIÓN | D4: GESTIÓN | E4: SERVICIOS RETENIDOS | F4: SERVICIOS CANCELADOS | H4: LLAMADAS | I4: RETENIDOS HOGAR | J4: CAN HOGAR | K4: RETENIDOS MOVIL | L4: CAN MOVIL | M4: INF_NIA | N4: IDENTIDA | O4: GES_NCC | P4: MAL TRANSFER | Q4: LLAMADA CAIDA | T4: RETE | U4: EFEC | V4: EFEC | W4: EFEC | Y4: LISTA | Z4: SERVICIOS | AA4: SERVICIOS
H5: =COUNT(B5:B50) -> 0 | I5: =COUNTIF($D$5:$D$50,"RETENIDO HOGAR") -> 0 | J5: =COUNTIF($D$5:$D$50,"CANCELADO HOGAR") -> 0 | K5: =COUNTIF($D$5:$D$50,"RETENIDO MOVIL") -> 0 | L5: =COUNTIF($D$5:$D$50,"CANCELADO MOVIL") -> 0 | M5: =COUNTIF(D5:D50,"INF_NIA") -> 0 | N5: =COUNTIF(D5:D50,"IDENTIDA") -> 0 | O5: =COUNTIF(D5:D50,"GES_NCC") -> 0 | P5: =COUNTIF($D$5:$D$50,"MAL TRANSFERIDA") -> 0 | Q5: =COUNTIF($D$5:$D$50,"LLAMADA CAIDA") -> 0 | U5: 0.74 | V5: 0.76 | W5: 0.78 | Y5: RETENIDO HOGAR | Z5: 1 | AA5: 1
T6: 17 | U6: 2300 | V6: 2600 | W6: 2900 | Y6: CANCELADO HOGAR | Z6: 2
T7: 19 | U7: 2700 | V7: 3000 | W7: 3300 | Y7: RETENIDO MOVIL | Z7: 3
H8: EFECTIVIDAD DIA HOGAR | K8: EFECTIVIDAD DIA MOVIL | N8: %MARCACIONES | P8: EFECTIVIDAD DIA GENERAL | T8: 21 | U8: 3000 | V8: 3300 | W8: 3600 | Y8: CANCELADO MOVIL
T9: 23 | U9: 3300 | V9: 3600 | W9: 3900 | Y9: INF_NIA
Y10: IDENTIDA
H11: =IFERROR(I5/SUM(I5:J5),"-") -> - | K11: =IFERROR(K5/SUM(K5:L5),"-") -> - | N11: {=IFERROR(SUM(I5:O5/H5),"-")} -> - | P11: =IFERROR(SUM(I5,K5)/SUM(I5:L5),"-") -> - | Y11: GES_NCC
Y12: MAL TRANSFERIDA
Y13: LLAMADA CAIDA
J15: SERVICIOS RETENIDOS | N15: SERVICIOS CANCELADOS
J18: =IFERROR(SUM($E$5:$E$50),"-") -> 0 | N18: =SUM(F5:F50) -> 0
I21: COMISIÓN DEL DÍA
I25: =IF(AND(J18>=T9,O2>=W5),J18*W9,IF(AND(J18>=T8,J18<T9,O2>=W5),J18*W8,IF(AND(J18>=T7,J18<T8,O2>=W5),J18*W7,IF(AND(J18>=T6,J18<T7,O2>=W5),J18*W6,IF(AND(J18>=T9,O2>=V5,O2<W5),J18*V9,IF(AND(J18>=T9,O2>=V5,O2<W5),J18*V8,IF(AND(J18>=T7,J18<T8,O2>=V5,O2<W5),J18*V7,IF(AND(J18>=T6,J18<T7,O2>=V5,O2<W5),J18*V6,IF(AND(J18>=T9,O2>=U5,O2<V5),J18*U9,IF(AND(J18>=T8,J18<T9,O2>=U5,O2<V5),J18*U8,IF(AND(J18>=T7,J18<T8,O2>=U5,O2<V5),J18*U7,IF(AND(J18>=T6,J18<T7,O2>=U5,O2<V5),J18*U6,"MUY SUAVE EN RETENIDOS 🥱")))))))))))) -> MUY SUAVE EN RETENIDOS 🥱

Sheet 05-09
B2: MENÚ PRINCIPAL | C2: RETENCIÓN | E2: EFECTIVIDAD HOGAR | G2: =GENERAL!B7 -> 1 | I2: EFECTIVIDAD MOVIL | K2: =GENERAL!E7 -> - | M2: EFECTIVIDAD MENSUAL | O2: =GENERAL!K7 -> 1
B4: NÚMERO/ CUENTA | C4: OBSERVACIÓN | D4: GESTIÓN | E4: SERVICIOS RETENIDOS | F4: SERVICIOS CANCELADOS | H4: LLAMADAS | I4: RETENIDOS HOGAR | J4: CAN HOGAR | K4: RETENIDOS MOVIL | L4: CAN MOVIL | M4: INF_NIA | N4: IDENTIDA | O4: GES_NCC | P4: MAL TRANSFER | Q4: LLAMADA CAIDA | T4: RETE | U4: EFEC | V4: EFEC | W4: EFEC | Y4: LISTA | Z4: SERVICIOS | AA4: SERVICIOS
H5: =COUNT(B5:B50) -> 0 | I5: =COUNTIF($D$5:$D$50,"RETENIDO HOGAR") -> 0 | J5: =COUNTIF($D$5:$D$50,"CANCELADO HOGAR") -> 0 | K5: =COUNTIF($D$5:$D$50,"RETENIDO MOVIL") -> 0 | L5: =COUNTIF($D$5:$D$50,"CANCELADO MOVIL") -> 0 | M5: =COUNTIF(D5:D50,"INF_NIA") -> 0 | N5: =COUNTIF(D5:D50,"IDENTIDA") -> 0 | O5: =COUNTIF(D5:D50,"GES_NCC") -> 0 | P5: =COUNTIF($D$5:$D$50,"MAL TRANSFERIDA") -> 0 | Q5: =COUNTIF($D$5:$D$50,"LLAMADA CAIDA") -> 0 | U5: 0.74 | V5: 0.76 | W5: 0.78 | Y5: RETENIDO HOGAR | Z5: 1 | AA5: 1
T6: 17 | U6: 2300 | V6: 2600 | W6: 2900 | Y6: CANCELADO HOGAR | Z6: 2
T7: 19 | U7: 2700 | V7: 3000 | W7: 3300 | Y7: RETENIDO MOVIL | Z7: 3
H8: EFECTIVIDAD DIA HOGAR | K8: EFECTIVIDAD DIA MOVIL | N8: %MARCACIONES | P8: EFECTIVIDAD DIA GENERAL | T8: 21 | U8: 3000 | V8: 3300 | W8: 3600 | Y8: CANCELADO MOVIL
T9: 23 | U9: 3300 | V9: 3600 | W9: 3900 | Y9: INF_NIA
Y10: IDENTIDA
H11: =IFERROR(I5/SUM(I5:J5),"-") -> - | K11: =IFERROR(K5/SUM(K5:L5),"-") -> - | N11: {=IFERROR(SUM(I5:O5/H5),"-")} -> - | P11: =IFERROR(SUM(I5,K5)/SUM(I5:L5),"-") -> - | Y11: GES_NCC
Y12: MAL TRANSFERIDA
Y13: LLAMADA CAIDA
J15: SERVICIOS RETENIDOS | N15: SERVICIOS CANCELADOS
J18: =IFERROR(SUM($E$5:$E$50),"-") -> 0 | N18: =SUM(F5:F50) -> 0
I21: COMISIÓN DEL DÍA
I25: =IF(AND(J18>=T9,O2>=W5),J18*W9,IF(AND(J18>=T8,J18<T9,O2>=W5),J18*W8,IF(AND(J18>=T7,J18<T8,O2>=W5),J18*W7,IF(AND(J18>=T6,J18<T7,O2>=W5),J18*W6,IF(AND(J18>=T9,O2>=V5,O2<W5),J18*V9,IF(AND(J18>=T9,O2>=V5,O2<W5),J18*V8,IF(AND(J18>=T7,J18<T8,O2>=V5,O2<W5),J18*V7,IF(AND(J18>=T6,J18<T7,O2>=V5,O2<W5),J18*V6,IF(AND(J18>=T9,O2>=U5,O2<V5),J18*U9,IF(AND(J18>=T8,J18<T9,O2>=U5,O2<V5),J18*U8,IF(AND(J18>=T7,J18<T8,O2>=U5,O2<V5),J18*U7,IF(AND(J18>=T6,J18<T7,O2>=U5,O2<V5),J18*U6,"MUY SUAVE EN RETENIDOS 🥱")))))))))))) -> MUY SUAVE EN RETENIDOS 🥱

Sheet 06-09
B2: MENÚ PRINCIPAL | C2: RETENCIÓN | E2: EFECTIVIDAD HOGAR | G2: =GENERAL!B7 -> 1 | I2: EFECTIVIDAD MOVIL | K2: =GENERAL!E7 -> - | M2: EFECTIVIDAD MENSUAL | O2: =GENERAL!K7 -> 1
B4: NÚMERO/ CUENTA | C4: OBSERVACIÓN | D4: GESTIÓN | E4: SERVICIOS RETENIDOS | F4: SERVICIOS CANCELADOS | H4: LLAMADAS | I4: RETENIDOS HOGAR | J4: CAN HOGAR | K4: RETENIDOS MOVIL | L4: CAN MOVIL | M4: INF_NIA | N4: IDENTIDA | O4: GES_NCC | P4: MAL TRANSFER | Q4: LLAMADA CAIDA | T4: RETE | U4: EFEC | V4: EFEC | W4: EFEC | Y4: LISTA | Z4: SERVICIOS | AA4: SERVICIOS
H5: =COUNT(B5:B50) -> 0 | I5: =COUNTIF($D$5:$D$50,"RETENIDO HOGAR") -> 0 | J5: =COUNTIF($D$5:$D$50,"CANCELADO HOGAR") -> 0 | K5: =COUNTIF($D$5:$D$50,"RETENIDO MOVIL") -> 0 | L5: =COUNTIF($D$5:$D$50,"CANCELADO MOVIL") -> 0 | M5: =COUNTIF(D5:D50,"INF_NIA") -> 0 | N5: =COUNTIF(D5:D50,"IDENTIDA") -> 0 | O5: =COUNTIF(D5:D50,"GES_NCC") -> 0 | P5: =COUNTIF($D$5:$D$50,"MAL TRANSFERIDA") -> 0 | Q5: =COUNTIF($D$5:$D$50,"LLAMADA CAIDA") -> 0 | U5: 0.74 | V5: 0.76 | W5: 0.78 | Y5: RETENIDO HOGAR | Z5: 1 | AA5: 1
T6: 17 | U6: 2300 | V6: 2600 | W6: 2900 | Y6: CANCELADO HOGAR | Z6: 2
T7: 19 | U7: 2700 | V7: 3000 | W7: 3300 | Y7: RETENIDO MOVIL | Z7: 3
H8: EFECTIVIDAD DIA HOGAR | K8: EFECTIVIDAD DIA MOVIL | N8: %MARCACIONES | P8: EFECTIVIDAD DIA GENERAL | T8: 21 | U8: 3000 | V8: 3300 | W8: 3600 | Y8: CANCELADO MOVIL
T9: 23 | U9: 3300 | V9: 3600 | W9: 3900 | Y9: INF_NIA
Y10: IDENTIDA
H11: =IFERROR(I5/SUM(I5:J5),"-") -> - | K11: =IFERROR(K5/SUM(K5:L5),"-") -> - | N11: {=IFERROR(SUM(I5:O5/H5),"-")} -> - | P11: =IFERROR(SUM(I5,K5)/SUM(I5:L5),"-") -> - | Y11: GES_NCC
Y12: MAL TRANSFERIDA
Y13: LLAMADA CAIDA
J15: SERVICIOS RETENIDOS | N15: SERVICIOS CANCELADOS
J18: =IFERROR(SUM($E$5:$E$50),"-") -> 0 | N18: =SUM(F5:F50) -> 0
I21: COMISIÓN DEL DÍA
I25: =IF(AND(J18>=T9,O2>=W5),J18*W9,IF(AND(J18>=T8,J18<T9,O2>=W5),J18*W8,IF(AND(J18>=T7,J18<T8,O2>=W5),J18*W7,IF(AND(J18>=T6,J18<T7,O2>=W5),J18*W6,IF(AND(J18>=T9,O2>=V5,O2<W5),J18*V9,IF(AND(J18>=T9,O2>=V5,O2<W5),J18*V8,IF(AND(J18>=T7,J18<T8,O2>=V5,O2<W5),J18*V7,IF(AND(J18>=T6,J18<T7,O2>=V5,O2<W5),J18*V6,IF(AND(J18>=T9,O2>=U5,O2<V5),J18*U9,IF(AND(J18>=T8,J18<T9,O2>=U5,O2<V5),J18*U8,IF(AND(J18>=T7,J18<T8,O2>=U5,O2<V5),J18*U7,IF(AND(J18>=T6,J18<T7,O2>=U5,O2<V5),J18*U6,"MUY SUAVE EN RETENIDOS 🥱")))))))))))) -> MUY SUAVE EN RETENIDOS 🥱

Sheet 08-09
B2: MENÚ PRINCIPAL | C2: RETENCIÓN | E2: EFECTIVIDAD HOGAR | G2: =GENERAL!B7 -> 1 | I2: EFECTIVIDAD MOVIL | K2: =GENERAL!E7 -> - | M2: EFECTIVIDAD MENSUAL | O2: =GENERAL!K7 -> 1
B4: NÚMERO/ CUENTA | C4: OBSERVACIÓN | D4: GESTIÓN | E4: SERVICIOS RETENIDOS | F4: SERVICIOS CANCELADOS | H4: LLAMADAS | I4: RETENIDOS HOGAR | J4: CAN HOGAR | K4: RETENIDOS MOVIL | L4: CAN MOVIL | M4: INF_NIA | N4: IDENTIDA | O4: GES_NCC | P4: MAL TRANSFER | Q4: LLAMADA CAIDA | T4: RETE | U4: EFEC | V4: EFEC | W4: EFEC | Y4: LISTA | Z4: SERVICIOS | AA4: SERVICIOS
H5: =COUNT(B5:B50) -> 0 | I5: =COUNTIF($D$5:$D$50,"RETENIDO HOGAR") -> 0 | J5: =COUNTIF($D$5:$D$50,"CANCELADO HOGAR") -> 0 | K5: =COUNTIF($D$5:$D$50,"RETENIDO MOVIL") -> 0 | L5: =COUNTIF($D$5:$D$50,"CANCELADO MOVIL") -> 0 | M5: =COUNTIF(D5:D50,"INF_NIA") -> 0 | N5: =COUNTIF(D5:D50,"IDENTIDA") -> 0 | O5: =COUNTIF(D5:D50,"GES_NCC") -> 0 | P5: =COUNTIF($D$5:$D$50,"MAL TRANSFERIDA") -> 0 | Q5: =COUNTIF($D$5:$D$50,"LLAMADA CAIDA") -> 0 | U5: 0.74 | V5: 0.76 | W5: 0.78 | Y5: RETENIDO HOGAR | Z5: 1 | AA5: 1
T6: 17 | U6: 2300 | V6: 2600 | W6: 2900 | Y6: CANCELADO HOGAR | Z6: 2
T7: 19 | U7: 2700 | V7: 3000 | W7: 3300 | Y7: RETENIDO MOVIL | Z7: 3
H8: EFECTIVIDAD DIA HOGAR | K8: EFECTIVIDAD DIA MOVIL | N8: %MARCACIONES | P8: EFECTIVIDAD DIA GENERAL | T8: 21 | U8: 3000 | V8: 3300 | W8: 3600 | Y8: CANCELADO MOVIL
T9: 23 | U9: 3300 | V9: 3600 | W9: 3900 | Y9: INF_NIA
Y10: IDENTIDA
H11: =IFERROR(I5/SUM(I5:J5),"-") -> - | K11: =IFERROR(K5/SUM(K5:L5),"-") -> - | N11: {=IFERROR(SUM(I5:O5/H5),"-")} -> - | P11: =IFERROR(SUM(I5,K5)/SUM(I5:L5),"-") -> - | Y11: GES_NCC
Y12: MAL TRANSFERIDA
Y13: LLAMADA CAIDA
J15: SERVICIOS RETENIDOS | N15: SERVICIOS CANCELADOS
J18: =IFERROR(SUM($E$5:$E$50),"-") -> 0 | N18: =SUM(F5:F50) -> 0
I21: COMISIÓN DEL DÍA
I25: =IF(AND(J18>=T9,O2>=W5),J18*W9,IF(AND(J18>=T8,J18<T9,O2>=W5),J18*W8,IF(AND(J18>=T7,J18<T8,O2>=W5),J18*W7,IF(AND(J18>=T6,J18<T7,O2>=W5),J18*W6,IF(AND(J18>=T9,O2>=V5,O2<W5),J18*V9,IF(AND(J18>=T9,O2>=V5,O2<W5),J18*V8,IF(AND(J18>=T7,J18<T8,O2>=V5,O2<W5),J18*V7,IF(AND(J18>=T6,J18<T7,O2>=V5,O2<W5),J18*V6,IF(AND(J18>=T9,O2>=U5,O2<V5),J18*U9,IF(AND(J18>=T8,J18<T9,O2>=U5,O2<V5),J18*U8,IF(AND(J18>=T7,J18<T8,O2>=U5,O2<V5),J18*U7,IF(AND(J18>=T6,J18<T7,O2>=U5,O2<V5),J18*U6,"MUY SUAVE EN RETENIDOS 🥱")))))))))))) -> MUY SUAVE EN RETENIDOS 🥱

Sheet 09-09
B2: MENÚ PRINCIPAL | C2: RETENCIÓN | E2: EFECTIVIDAD HOGAR | G2: =GENERAL!B7 -> 1 | I2: EFECTIVIDAD MOVIL | K2: =GENERAL!E7 -> - | M2: EFECTIVIDAD MENSUAL | O2: =GENERAL!K7 -> 1
B4: NÚMERO/ CUENTA | C4: OBSERVACIÓN | D4: GESTIÓN | E4: SERVICIOS RETENIDOS | F4: SERVICIOS CANCELADOS | H4: LLAMADAS | I4: RETENIDOS HOGAR | J4: CAN HOGAR | K4: RETENIDOS MOVIL | L4: CAN MOVIL | M4: INF_NIA | N4: IDENTIDA | O4: GES_NCC | P4: MAL TRANSFER | Q4: LLAMADA CAIDA | T4: RETE | U4: EFEC | V4: EFEC | W4: EFEC | Y4: LISTA | Z4: SERVICIOS | AA4: SERVICIOS
H5: =COUNT(B5:B50) -> 0 | I5: =COUNTIF($D$5:$D$50,"RETENIDO HOGAR") -> 0 | J5: =COUNTIF($D$5:$D$50,"CANCELADO HOGAR") -> 0 | K5: =COUNTIF($D$5:$D$50,"RETENIDO MOVIL") -> 0 | L5: =COUNTIF($D$5:$D$50,"CANCELADO MOVIL") -> 0 | M5: =COUNTIF(D5:D50,"INF_NIA") -> 0 | N5: =COUNTIF(D5:D50,"IDENTIDA") -> 0 | O5: =COUNTIF(D5:D50,"GES_NCC") -> 0 | P5: =COUNTIF($D$5:$D$50,"MAL TRANSFERIDA") -> 0 | Q5: =COUNTIF($D$5:$D$50,"LLAMADA CAIDA") -> 0 | U5: 0.74 | V5: 0.76 | W5: 0.78 | Y5: RETENIDO HOGAR | Z5: 1 | AA5: 1
T6: 17 | U6: 2300 | V6: 2600 | W6: 2900 | Y6: CANCELADO HOGAR | Z6: 2
T7: 19 | U7: 2700 | V7: 3000 | W7: 3300 | Y7: RETENIDO MOVIL | Z7: 3
H8: EFECTIVIDAD DIA HOGAR | K8: EFECTIVIDAD DIA MOVIL | N8: %MARCACIONES | P8: EFECTIVIDAD DIA GENERAL | T8: 21 | U8: 3000 | V8: 3300 | W8: 3600 | Y8: CANCELADO MOVIL
T9: 23 | U9: 3300 | V9: 3600 | W9: 3900 | Y9: INF_NIA
Y10: IDENTIDA
H11: =IFERROR(I5/SUM(I5:J5),"-") -> - | K11: =IFERROR(K5/SUM(K5:L5),"-") -> - | N11: {=IFERROR(SUM(I5:O5/H5),"-")} -> - | P11: =IFERROR(SUM(I5,K5)/SUM(I5:L5),"-") -> - | Y11: GES_NCC
Y12: MAL TRANSFERIDA
Y13: LLAMADA CAIDA
J15: SERVICIOS RETENIDOS | N15: SERVICIOS CANCELADOS
J18: =IFERROR(SUM($E$5:$E$50),"-") -> 0 | N18: =SUM(F5:F50) -> 0
I21: COMISIÓN DEL DÍA
I25: =IF(AND(J18>=T9,O2>=W5),J18*W9,IF(AND(J18>=T8,J18<T9,O2>=W5),J18*W8,IF(AND(J18>=T7,J18<T8,O2>=W5),J18*W7,IF(AND(J18>=T6,J18<T7,O2>=W5),J18*W6,IF(AND(J18>=T9,O2>=V5,O2<W5),J18*V9,IF(AND(J18>=T9,O2>=V5,O2<W5),J18*V8,IF(AND(J18>=T7,J18<T8,O2>=V5,O2<W5),J18*V7,IF(AND(J18>=T6,J18<T7,O2>=V5,O2<W5),J18*V6,IF(AND(J18>=T9,O2>=U5,O2<V5),J18*U9,IF(AND(J18>=T8,J18<T9,O2>=U5,O2<V5),J18*U8,IF(AND(J18>=T7,J18<T8,O2>=U5,O2<V5),J18*U7,IF(AND(J18>=T6,J18<T7,O2>=U5,O2<V5),J18*U6,"MUY SUAVE EN RETENIDOS 🥱")))))))))))) -> MUY SUAVE EN RETENIDOS 🥱

Sheet 10-09
B2: MENÚ PRINCIPAL | C2: RETENCIÓN | E2: EFECTIVIDAD HOGAR | G2: =GENERAL!B7 -> 1 | I2: EFECTIVIDAD MOVIL | K2: =GENERAL!E7 -> - | M2: EFECTIVIDAD MENSUAL | O2: =GENERAL!K7 -> 1
B4: NÚMERO/ CUENTA | C4: OBSERVACIÓN | D4: GESTIÓN | E4: SERVICIOS RETENIDOS | F4: SERVICIOS CANCELADOS | H4: LLAMADAS | I4: RETENIDOS HOGAR | J4: CAN HOGAR | K4: RETENIDOS MOVIL | L4: CAN MOVIL | M4: INF_NIA | N4: IDENTIDA | O4: GES_NCC | P4: MAL TRANSFER | Q4: LLAMADA CAIDA | T4: RETE | U4: EFEC | V4: EFEC | W4: EFEC | Y4: LISTA | Z4: SERVICIOS | AA4: SERVICIOS
H5: =COUNT(B5:B50) -> 0 | I5: =COUNTIF($D$5:$D$50,"RETENIDO HOGAR") -> 0 | J5: =COUNTIF($D$5:$D$50,"CANCELADO HOGAR") -> 0 | K5: =COUNTIF($D$5:$D$50,"RETENIDO MOVIL") -> 0 | L5: =COUNTIF($D$5:$D$50,"CANCELADO MOVIL") -> 0 | M5: =COUNTIF(D5:D50,"INF_NIA") -> 0 | N5: =COUNTIF(D5:D50,"IDENTIDA") -> 0 | O5: =COUNTIF(D5:D50,"GES_NCC") -> 0 | P5: =COUNTIF($D$5:$D$50,"MAL TRANSFERIDA") -> 0 | Q5: =COUNTIF($D$5:$D$50,"LLAMADA CAIDA") -> 0 | U5: 0.74 | V5: 0.76 | W5: 0.78 | Y5: RETENIDO HOGAR | Z5: 1 | AA5: 1
T6: 17 | U6: 2300 | V6: 2600 | W6: 2900 | Y6: CANCELADO HOGAR | Z6: 2
T7: 19 | U7: 2700 | V7: 3000 | W7: 3300 | Y7: RETENIDO MOVIL | Z7: 3
H8: EFECTIVIDAD DIA HOGAR | K8: EFECTIVIDAD DIA MOVIL | N8: %MARCACIONES | P8: EFECTIVIDAD DIA GENERAL | T8: 21 | U8: 3000 | V8: 3300 | W8: 3600 | Y8: CANCELADO MOVIL
T9: 23 | U9: 3300 | V9: 3600 | W9: 3900 | Y9: INF_NIA
Y10: IDENTIDA
H11: =IFERROR(I5/SUM(I5:J5),"-") -> - | K11: =IFERROR(K5/SUM(K5:L5),"-") -> - | N11: {=IFERROR(SUM(I5:O5/H5),"-")} -> - | P11: =IFERROR(SUM(I5,K5)/SUM(I5:L5),"-") -> - | Y11: GES_NCC
Y12: MAL TRANSFERIDA
Y13: LLAMADA CAIDA
J15: SERVICIOS RETENIDOS | N15: SERVICIOS CANCELADOS
J18: =IFERROR(SUM($E$5:$E$50),"-") -> 0 | N18: =SUM(F5:F50) -> 0
I21: COMISIÓN DEL DÍA
I25: =IF(AND(J18>=T9,O2>=W5),J18*W9,IF(AND(J18>=T8,J18<T9,O2>=W5),J18*W8,IF(AND(J18>=T7,J18<T8,O2>=W5),J18*W7,IF(AND(J18>=T6,J18<T7,O2>=W5),J18*W6,IF(AND(J18>=T9,O2>=V5,O2<W5),J18*V9,IF(AND(J18>=T9,O2>=V5,O2<W5),J18*V8,IF(AND(J18>=T7,J18<T8,O2>=V5,O2<W5),J18*V7,IF(AND(J18>=T6,J18<T7,O2>=V5,O2<W5),J18*V6,IF(AND(J18>=T9,O2>=U5,O2<V5),J18*U9,IF(AND(J18>=T8,J18<T9,O2>=U5,O2<V5),J18*U8,IF(AND(J18>=T7,J18<T8,O2>=U5,O2<V5),J18*U7,IF(AND(J18>=T6,J18<T7,O2>=U5,O2<V5),J18*U6,"MUY SUAVE EN RETENIDOS 🥱")))))))))))) -> MUY SUAVE EN RETENIDOS 🥱

Sheet 11-09
B2: MENÚ PRINCIPAL | C2: RETENCIÓN | E2: EFECTIVIDAD HOGAR | G2: =GENERAL!B7 -> 1 | I2: EFECTIVIDAD MOVIL | K2: =GENERAL!E7 -> - | M2: EFECTIVIDAD MENSUAL | O2: =GENERAL!K7 -> 1
B4: NÚMERO/ CUENTA | C4: OBSERVACIÓN | D4: GESTIÓN | E4: SERVICIOS RETENIDOS | F4: SERVICIOS CANCELADOS | H4: LLAMADAS | I4: RETENIDOS HOGAR | J4: CAN HOGAR | K4: RETENIDOS MOVIL | L4: CAN MOVIL | M4: INF_NIA | N4: IDENTIDA | O4: GES_NCC | P4: MAL TRANSFER | Q4: LLAMADA CAIDA | T4: RETE | U4: EFEC | V4: EFEC | W4: EFEC | Y4: LISTA | Z4: SERVICIOS | AA4: SERVICIOS
H5: =COUNT(B5:B50) -> 0 | I5: =COUNTIF($D$5:$D$50,"RETENIDO HOGAR") -> 0 | J5: =COUNTIF($D$5:$D$50,"CANCELADO HOGAR") -> 0 | K5: =COUNTIF($D$5:$D$50,"RETENIDO MOVIL") -> 0 | L5: =COUNTIF($D$5:$D$50,"CANCELADO MOVIL") -> 0 | M5: =COUNTIF(D5:D50,"INF_NIA") -> 0 | N5: =COUNTIF(D5:D50,"IDENTIDA") -> 0 | O5: =COUNTIF(D5:D50,"GES_NCC") -> 0 | P5: =COUNTIF($D$5:$D$50,"MAL TRANSFERIDA") -> 0 | Q5: =COUNTIF($D$5:$D$50,"LLAMADA CAIDA") -> 0 | U5: 0.74 | V5: 0.76 | W5: 0.78 | Y5: RETENIDO HOGAR | Z5: 1 | AA5: 1
T6: 17 | U6: 2300 | V6: 2600 | W6: 2900 | Y6: CANCELADO HOGAR | Z6: 2
T7: 19 | U7: 2700 | V7: 3000 | W7: 3300 | Y7: RETENIDO MOVIL | Z7: 3
H8: EFECTIVIDAD DIA HOGAR | K8: EFECTIVIDAD DIA MOVIL | N8: %MARCACIONES | P8: EFECTIVIDAD DIA GENERAL | T8: 21 | U8: 3000 | V8: 3300 | W8: 3600 | Y8: CANCELADO MOVIL
T9: 23 | U9: 3300 | V9: 3600 | W9: 3900 | Y9: INF_NIA
Y10: IDENTIDA
H11: =IFERROR(I5/SUM(I5:J5),"-") -> - | K11: =IFERROR(K5/SUM(K5:L5),"-") -> - | N11: {=IFERROR(SUM(I5:O5/H5),"-")} -> - | P11: =IFERROR(SUM(I5,K5)/SUM(I5:L5),"-") -> - | Y11: GES_NCC
Y12: MAL TRANSFERIDA
Y13: LLAMADA CAIDA
J15: SERVICIOS RETENIDOS | N15: SERVICIOS CANCELADOS
J18: =IFERROR(SUM($E$5:$E$50),"-") -> 0 | N18: =SUM(F5:F50) -> 0
I21: COMISIÓN DEL DÍA
I25: =IF(AND(J18>=T9,O2>=W5),J18*W9,IF(AND(J18>=T8,J18<T9,O2>=W5),J18*W8,IF(AND(J18>=T7,J18<T8,O2>=W5),J18*W7,IF(AND(J18>=T6,J18<T7,O2>=W5),J18*W6,IF(AND(J18>=T9,O2>=V5,O2<W5),J18*V9,IF(AND(J18>=T9,O2>=V5,O2<W5),J18*V8,IF(AND(J18>=T7,J18<T8,O2>=V5,O2<W5),J18*V7,IF(AND(J18>=T6,J18<T7,O2>=V5,O2<W5),J18*V6,IF(AND(J18>=T9,O2>=U5,O2<V5),J18*U9,IF(AND(J18>=T8,J18<T9,O2>=U5,O2<V5),J18*U8,IF(AND(J18>=T7,J18<T8,O2>=U5,O2<V5),J18*U7,IF(AND(J18>=T6,J18<T7,O2>=U5,O2<V5),J18*U6,"MUY SUAVE EN RETENIDOS 🥱")))))))))))) -> MUY SUAVE EN RETENIDOS 🥱

Sheet 12-09
B2: MENÚ PRINCIPAL | C2: RETENCIÓN | E2: EFECTIVIDAD HOGAR | G2: =GENERAL!B7 -> 1 | I2: EFECTIVIDAD MOVIL | K2: =GENERAL!E7 -> - | M2: EFECTIVIDAD MENSUAL | O2: =GENERAL!K7 -> 1
B4: NÚMERO/ CUENTA | C4: OBSERVACIÓN | D4: GESTIÓN | E4: SERVICIOS RETENIDOS | F4: SERVICIOS CANCELADOS | H4: LLAMADAS | I4: RETENIDOS HOGAR | J4: CAN HOGAR | K4: RETENIDOS MOVIL | L4: CAN MOVIL | M4: INF_NIA | N4: IDENTIDA | O4: GES_NCC | P4: MAL TRANSFER | Q4: LLAMADA CAIDA | T4: RETE | U4: EFEC | V4: EFEC | W4: EFEC | Y4: LISTA | Z4: SERVICIOS | AA4: SERVICIOS
H5: =COUNT(B5:B50) -> 0 | I5: =COUNTIF($D$5:$D$50,"RETENIDO HOGAR") -> 0 | J5: =COUNTIF($D$5:$D$50,"CANCELADO HOGAR") -> 0 | K5: =COUNTIF($D$5:$D$50,"RETENIDO MOVIL") -> 0 | L5: =COUNTIF($D$5:$D$50,"CANCELADO MOVIL") -> 0 | M5: =COUNTIF(D5:D50,"INF_NIA") -> 0 | N5: =COUNTIF(D5:D50,"IDENTIDA") -> 0 | O5: =COUNTIF(D5:D50,"GES_NCC") -> 0 | P5: =COUNTIF($D$5:$D$50,"MAL TRANSFERIDA") -> 0 | Q5: =COUNTIF($D$5:$D$50,"LLAMADA CAIDA") -> 0 | U5: 0.74 | V5: 0.76 | W5: 0.78 | Y5: RETENIDO HOGAR | Z5: 1 | AA5: 1
T6: 17 | U6: 2300 | V6: 2600 | W6: 2900 | Y6: CANCELADO HOGAR | Z6: 2
T7: 19 | U7: 2700 | V7: 3000 | W7: 3300 | Y7: RETENIDO MOVIL | Z7: 3
H8: EFECTIVIDAD DIA HOGAR | K8: EFECTIVIDAD DIA MOVIL | N8: %MARCACIONES | P8: EFECTIVIDAD DIA GENERAL | T8: 21 | U8: 3000 | V8: 3300 | W8: 3600 | Y8: CANCELADO MOVIL
T9: 23 | U9: 3300 | V9: 3600 | W9: 3900 | Y9: INF_NIA
Y10: IDENTIDA
H11: =IFERROR(I5/SUM(I5:J5),"-") -> - | K11: =IFERROR(K5/SUM(K5:L5),"-") -> - | N11: {=IFERROR(SUM(I5:O5/H5),"-")} -> - | P11: =IFERROR(SUM(I5,K5)/SUM(I5:L5),"-") -> - | Y11: GES_NCC
Y12: MAL TRANSFERIDA
Y13: LLAMADA CAIDA
J15: SERVICIOS RETENIDOS | N15: SERVICIOS CANCELADOS
J18: =IFERROR(SUM($E$5:$E$50),"-") -> 0 | N18: =SUM(F5:F50) -> 0
I21: COMISIÓN DEL DÍA
I25: =IF(AND(J18>=T9,O2>=W5),J18*W9,IF(AND(J18>=T8,J18<T9,O2>=W5),J18*W8,IF(AND(J18>=T7,J18<T8,O2>=W5),J18*W7,IF(AND(J18>=T6,J18<T7,O2>=W5),J18*W6,IF(AND(J18>=T9,O2>=V5,O2<W5),J18*V9,IF(AND(J18>=T9,O2>=V5,O2<W5),J18*V8,IF(AND(J18>=T7,J18<T8,O2>=V5,O2<W5),J18*V7,IF(AND(J18>=T6,J18<T7,O2>=V5,O2<W5),J18*V6,IF(AND(J18>=T9,O2>=U5,O2<V5),J18*U9,IF(AND(J18>=T8,J18<T9,O2>=U5,O2<V5),J18*U8,IF(AND(J18>=T7,J18<T8,O2>=U5,O2<V5),J18*U7,IF(AND(J18>=T6,J18<T7,O2>=U5,O2<V5),J18*U6,"MUY SUAVE EN RETENIDOS 🥱")))))))))))) -> MUY SUAVE EN RETENIDOS 🥱

Sheet 13-09
B2: MENÚ PRINCIPAL | C2: RETENCIÓN | E2: EFECTIVIDAD HOGAR | G2: =GENERAL!B7 -> 1 | I2: EFECTIVIDAD MOVIL | K2: =GENERAL!E7 -> - | M2: EFECTIVIDAD MENSUAL | O2: =GENERAL!K7 -> 1
B4: NÚMERO/ CUENTA | C4: OBSERVACIÓN | D4: GESTIÓN | E4: SERVICIOS RETENIDOS | F4: SERVICIOS CANCELADOS | H4: LLAMADAS | I4: RETENIDOS HOGAR | J4: CAN HOGAR | K4: RETENIDOS MOVIL | L4: CAN MOVIL | M4: INF_NIA | N4: IDENTIDA | O4: GES_NCC | P4: MAL TRANSFER | Q4: LLAMADA CAIDA | T4: RETE | U4: EFEC | V4: EFEC | W4: EFEC | Y4: LISTA | Z4: SERVICIOS | AA4: SERVICIOS
H5: =COUNT(B5:B50) -> 0 | I5: =COUNTIF($D$5:$D$50,"RETENIDO HOGAR") -> 0 | J5: =COUNTIF($D$5:$D$50,"CANCELADO HOGAR") -> 0 | K5: =COUNTIF($D$5:$D$50,"RETENIDO MOVIL") -> 0 | L5: =COUNTIF($D$5:$D$50,"CANCELADO MOVIL") -> 0 | M5: =COUNTIF(D5:D50,"INF_NIA") -> 0 | N5: =COUNTIF(D5:D50,"IDENTIDA") -> 0 | O5: =COUNTIF(D5:D50,"GES_NCC") -> 0 | P5: =COUNTIF($D$5:$D$50,"MAL TRANSFERIDA") -> 0 | Q5: =COUNTIF($D$5:$D$50,"LLAMADA CAIDA") -> 0 | U5: 0.74 | V5: 0.76 | W5: 0.78 | Y5: RETENIDO HOGAR | Z5: 1 | AA5: 1
T6: 17 | U6: 2300 | V6: 2600 | W6: 2900 | Y6: CANCELADO HOGAR | Z6: 2
T7: 19 | U7: 2700 | V7: 3000 | W7: 3300 | Y7: RETENIDO MOVIL | Z7: 3
H8: EFECTIVIDAD DIA HOGAR | K8: EFECTIVIDAD DIA MOVIL | N8: %MARCACIONES | P8: EFECTIVIDAD DIA GENERAL | T8: 21 | U8: 3000 | V8: 3300 | W8: 3600 | Y8: CANCELADO MOVIL
T9: 23 | U9: 3300 | V9: 3600 | W9: 3900 | Y9: INF_NIA
Y10: IDENTIDA
H11: =IFERROR(I5/SUM(I5:J5),"-") -> - | K11: =IFERROR(K5/SUM(K5:L5),"-") -> - | N11: {=IFERROR(SUM(I5:O5/H5),"-")} -> - | P11: =IFERROR(SUM(I5,K5)/SUM(I5:L5),"-") -> - | Y11: GES_NCC
Y12: MAL TRANSFERIDA
Y13: LLAMADA CAIDA
J15: SERVICIOS RETENIDOS | N15: SERVICIOS CANCELADOS
J18: =IFERROR(SUM($E$5:$E$50),"-") -> 0 | N18: =SUM(F5:F50) -> 0
I21: COMISIÓN DEL DÍA
I25: =IF(AND(J18>=T9,O2>=W5),J18*W9,IF(AND(J18>=T8,J18<T9,O2>=W5),J18*W8,IF(AND(J18>=T7,J18<T8,O2>=W5),J18*W7,IF(AND(J18>=T6,J18<T7,O2>=W5),J18*W6,IF(AND(J18>=T9,O2>=V5,O2<W5),J18*V9,IF(AND(J18>=T9,O2>=V5,O2<W5),J18*V8,IF(AND(J18>=T7,J18<T8,O2>=V5,O2<W5),J18*V7,IF(AND(J18>=T6,J18<T7,O2>=V5,O2<W5),J18*V6,IF(AND(J18>=T9,O2>=U5,O2<V5),J18*U9,IF(AND(J18>=T8,J18<T9,O2>=U5,O2<V5),J18*U8,IF(AND(J18>=T7,J18<T8,O2>=U5,O2<V5),J18*U7,IF(AND(J18>=T6,J18<T7,O2>=U5,O2<V5),J18*U6,"MUY SUAVE EN RETENIDOS 🥱")))))))))))) -> MUY SUAVE EN RETENIDOS 🥱

Sheet 15-09
B2: MENÚ PRINCIPAL | C2: RETENCIÓN | E2: EFECTIVIDAD HOGAR | G2: =GENERAL!B7 -> 1 | I2: EFECTIVIDAD MOVIL | K2: =GENERAL!E7 -> - | M2: EFECTIVIDAD MENSUAL | O2: =GENERAL!K7 -> 1
B4: NÚMERO/ CUENTA | C4: OBSERVACIÓN | D4: GESTIÓN | E4: SERVICIOS RETENIDOS | F4: SERVICIOS CANCELADOS | H4: LLAMADAS | I4: RETENIDOS HOGAR | J4: CAN HOGAR | K4: RETENIDOS MOVIL | L4: CAN MOVIL | M4: INF_NIA | N4: IDENTIDA | O4: GES_NCC | P4: MAL TRANSFER | Q4: LLAMADA CAIDA | T4: RETE | U4: EFEC | V4: EFEC | W4: EFEC | Y4: LISTA | Z4: SERVICIOS | AA4: SERVICIOS
H5: =COUNT(B5:B50) -> 0 | I5: =COUNTIF($D$5:$D$50,"RETENIDO HOGAR") -> 0 | J5: =COUNTIF($D$5:$D$50,"CANCELADO HOGAR") -> 0 | K5: =COUNTIF($D$5:$D$50,"RETENIDO MOVIL") -> 0 | L5: =COUNTIF($D$5:$D$50,"CANCELADO MOVIL") -> 0 | M5: =COUNTIF(D5:D50,"INF_NIA") -> 0 | N5: =COUNTIF(D5:D50,"IDENTIDA") -> 0 | O5: =COUNTIF(D5:D50,"GES_NCC") -> 0 | P5: =COUNTIF($D$5:$D$50,"MAL TRANSFERIDA") -> 0 | Q5: =COUNTIF($D$5:$D$50,"LLAMADA CAIDA") -> 0 | U5: 0.74 | V5: 0.76 | W5: 0.78 | Y5: RETENIDO HOGAR | Z5: 1 | AA5: 1
T6: 17 | U6: 2300 | V6: 2600 | W6: 2900 | Y6: CANCELADO HOGAR | Z6: 2
T7: 19 | U7: 2700 | V7: 3000 | W7: 3300 | Y7: RETENIDO MOVIL | Z7: 3
H8: EFECTIVIDAD DIA HOGAR | K8: EFECTIVIDAD DIA MOVIL | N8: %MARCACIONES | P8: EFECTIVIDAD DIA GENERAL | T8: 21 | U8: 3000 | V8: 3300 | W8: 3600 | Y8: CANCELADO MOVIL
T9: 23 | U9: 3300 | V9: 3600 | W9: 3900 | Y9: INF_NIA
Y10: IDENTIDA
H11: =IFERROR(I5/SUM(I5:J5),"-") -> - | K11: =IFERROR(K5/SUM(K5:L5),"-") -> - | N11: {=IFERROR(SUM(I5:O5/H5),"-")} -> - | P11: =IFERROR(SUM(I5,K5)/SUM(I5:L5),"-") -> - | Y11: GES_NCC
Y12: MAL TRANSFERIDA
Y13: LLAMADA CAIDA
J15: SERVICIOS RETENIDOS | N15: SERVICIOS CANCELADOS
J18: =IFERROR(SUM($E$5:$E$50),"-") -> 0 | N18: =SUM(F5:F50) -> 0
I21: COMISIÓN DEL DÍA
I25: =IF(AND(J18>=T9,O2>=W5),J18*W9,IF(AND(J18>=T8,J18<T9,O2>=W5),J18*W8,IF(AND(J18>=T7,J18<T8,O2>=W5),J18*W7,IF(AND(J18>=T6,J18<T7,O2>=W5),J18*W6,IF(AND(J18>=T9,O2>=V5,O2<W5),J18*V9,IF(AND(J18>=T9,O2>=V5,O2<W5),J18*V8,IF(AND(J18>=T7,J18<T8,O2>=V5,O2<W5),J18*V7,IF(AND(J18>=T6,J18<T7,O2>=V5,O2<W5),J18*V6,IF(AND(J18>=T9,O2>=U5,O2<V5),J18*U9,IF(AND(J18>=T8,J18<T9,O2>=U5,O2<V5),J18*U8,IF(AND(J18>=T7,J18<T8,O2>=U5,O2<V5),J18*U7,IF(AND(J18>=T6,J18<T7,O2>=U5,O2<V5),J18*U6,"MUY SUAVE EN RETENIDOS 🥱")))))))))))) -> MUY SUAVE EN RETENIDOS 🥱

Sheet 16-09
B2: MENÚ PRINCIPAL | C2: RETENCIÓN | E2: EFECTIVIDAD HOGAR | G2: =GENERAL!B7 -> 1 | I2: EFECTIVIDAD MOVIL | K2: =GENERAL!E7 -> - | M2: EFECTIVIDAD MENSUAL | O2: =GENERAL!K7 -> 1
B4: NÚMERO/ CUENTA | C4: OBSERVACIÓN | D4: GESTIÓN | E4: SERVICIOS RETENIDOS | F4: SERVICIOS CANCELADOS | H4: LLAMADAS | I4: RETENIDOS HOGAR | J4: CAN HOGAR | K4: RETENIDOS MOVIL | L4: CAN MOVIL | M4: INF_NIA | N4: IDENTIDA | O4: GES_NCC | P4: MAL TRANSFER | Q4: LLAMADA CAIDA | T4: RETE | U4: EFEC | V4: EFEC | W4: EFEC | Y4: LISTA | Z4: SERVICIOS | AA4: SERVICIOS
H5: =COUNT(B5:B50) -> 0 | I5: =COUNTIF($D$5:$D$50,"RETENIDO HOGAR") -> 0 | J5: =COUNTIF($D$5:$D$50,"CANCELADO HOGAR") -> 0 | K5: =COUNTIF($D$5:$D$50,"RETENIDO MOVIL") -> 0 | L5: =COUNTIF($D$5:$D$50,"CANCELADO MOVIL") -> 0 | M5: =COUNTIF(D5:D50,"INF_NIA") -> 0 | N5: =COUNTIF(D5:D50,"IDENTIDA") -> 0 | O5: =COUNTIF(D5:D50,"GES_NCC") -> 0 | P5: =COUNTIF($D$5:$D$50,"MAL TRANSFERIDA") -> 0 | Q5: =COUNTIF($D$5:$D$50,"LLAMADA CAIDA") -> 0 | U5: 0.74 | V5: 0.76 | W5: 0.78 | Y5: RETENIDO HOGAR | Z5: 1 | AA5: 1
T6: 17 | U6: 2300 | V6: 2600 | W6: 2900 | Y6: CANCELADO HOGAR | Z6: 2
T7: 19 | U7: 2700 | V7: 3000 | W7: 3300 | Y7: RETENIDO MOVIL | Z7: 3
H8: EFECTIVIDAD DIA HOGAR | K8: EFECTIVIDAD DIA MOVIL | N8: %MARCACIONES | P8: EFECTIVIDAD DIA GENERAL | T8: 21 | U8: 3000 | V8: 3300 | W8: 3600 | Y8: CANCELADO MOVIL
T9: 23 | U9: 3300 | V9: 3600 | W9: 3900 | Y9: INF_NIA
Y10: IDENTIDA
H11: =IFERROR(I5/SUM(I5:J5),"-") -> - | K11: =IFERROR(K5/SUM(K5:L5),"-") -> - | N11: {=IFERROR(SUM(I5:O5/H5),"-")} -> - | P11: =IFERROR(SUM(I5,K5)/SUM(I5:L5),"-") -> - | Y11: GES_NCC
Y12: MAL TRANSFERIDA
Y13: LLAMADA CAIDA
J15: SERVICIOS RETENIDOS | N15: SERVICIOS CANCELADOS
J18: =IFERROR(SUM($E$5:$E$50),"-") -> 0 | N18: =SUM(F5:F50) -> 0
I21: COMISIÓN DEL DÍA
I25: =IF(AND(J18>=T9,O2>=W5),J18*W9,IF(AND(J18>=T8,J18<T9,O2>=W5),J18*W8,IF(AND(J18>=T7,J18<T8,O2>=W5),J18*W7,IF(AND(J18>=T6,J18<T7,O2>=W5),J18*W6,IF(AND(J18>=T9,O2>=V5,O2<W5),J18*V9,IF(AND(J18>=T9,O2>=V5,O2<W5),J18*V8,IF(AND(J18>=T7,J18<T8,O2>=V5,O2<W5),J18*V7,IF(AND(J18>=T6,J18<T7,O2>=V5,O2<W5),J18*V6,IF(AND(J18>=T9,O2>=U5,O2<V5),J18*U9,IF(AND(J18>=T8,J18<T9,O2>=U5,O2<V5),J18*U8,IF(AND(J18>=T7,J18<T8,O2>=U5,O2<V5),J18*U7,IF(AND(J18>=T6,J18<T7,O2>=U5,O2<V5),J18*U6,"MUY SUAVE EN RETENIDOS 🥱")))))))))))) -> MUY SUAVE EN RETENIDOS 🥱

Sheet 17-09
B2: MENÚ PRINCIPAL | C2: RETENCIÓN | E2: EFECTIVIDAD HOGAR | G2: =GENERAL!B7 -> 1 | I2: EFECTIVIDAD MOVIL | K2: =GENERAL!E7 -> - | M2: EFECTIVIDAD MENSUAL | O2: =GENERAL!K7 -> 1
B4: NÚMERO/ CUENTA | C4: OBSERVACIÓN | D4: GESTIÓN | E4: SERVICIOS RETENIDOS | F4: SERVICIOS CANCELADOS | H4: LLAMADAS | I4: RETENIDOS HOGAR | J4: CAN HOGAR | K4: RETENIDOS MOVIL | L4: CAN MOVIL | M4: INF_NIA | N4: IDENTIDA | O4: GES_NCC | P4: MAL TRANSFER | Q4: LLAMADA CAIDA | T4: RETE | U4: EFEC | V4: EFEC | W4: EFEC | Y4: LISTA | Z4: SERVICIOS | AA4: SERVICIOS
H5: =COUNT(B5:B50) -> 0 | I5: =COUNTIF($D$5:$D$50,"RETENIDO HOGAR") -> 0 | J5: =COUNTIF($D$5:$D$50,"CANCELADO HOGAR") -> 0 | K5: =COUNTIF($D$5:$D$50,"RETENIDO MOVIL") -> 0 | L5: =COUNTIF($D$5:$D$50,"CANCELADO MOVIL") -> 0 | M5: =COUNTIF(D5:D50,"INF_NIA") -> 0 | N5: =COUNTIF(D5:D50,"IDENTIDA") -> 0 | O5: =COUNTIF(D5:D50,"GES_NCC") -> 0 | P5: =COUNTIF($D$5:$D$50,"MAL TRANSFERIDA") -> 0 | Q5: =COUNTIF($D$5:$D$50,"LLAMADA CAIDA") -> 0 | U5: 0.74 | V5: 0.76 | W5: 0.78 | Y5: RETENIDO HOGAR | Z5: 1 | AA5: 1
T6: 17 | U6: 2300 | V6: 2600 | W6: 2900 | Y6: CANCELADO HOGAR | Z6: 2
T7: 19 | U7: 2700 | V7: 3000 | W7: 3300 | Y7: RETENIDO MOVIL | Z7: 3
H8: EFECTIVIDAD DIA HOGAR | K8: EFECTIVIDAD DIA MOVIL | N8: %MARCACIONES | P8: EFECTIVIDAD DIA GENERAL | T8: 21 | U8: 3000 | V8: 3300 | W8: 3600 | Y8: CANCELADO MOVIL
T9: 23 | U9: 3300 | V9: 3600 | W9: 3900 | Y9: INF_NIA
Y10: IDENTIDA
H11: =IFERROR(I5/SUM(I5:J5),"-") -> - | K11: =IFERROR(K5/SUM(K5:L5),"-") -> - | N11: {=IFERROR(SUM(I5:O5/H5),"-")} -> - | P11: =IFERROR(SUM(I5,K5)/SUM(I5:L5),"-") -> - | Y11: GES_NCC
Y12: MAL TRANSFERIDA
Y13: LLAMADA CAIDA
J15: SERVICIOS RETENIDOS | N15: SERVICIOS CANCELADOS
J18: =IFERROR(SUM($E$5:$E$50),"-") -> 0 | N18: =SUM(F5:F50) -> 0
I21: COMISIÓN DEL DÍA
I25: =IF(AND(J18>=T9,O2>=W5),J18*W9,IF(AND(J18>=T8,J18<T9,O2>=W5),J18*W8,IF(AND(J18>=T7,J18<T8,O2>=W5),J18*W7,IF(AND(J18>=T6,J18<T7,O2>=W5),J18*W6,IF(AND(J18>=T9,O2>=V5,O2<W5),J18*V9,IF(AND(J18>=T9,O2>=V5,O2<W5),J18*V8,IF(AND(J18>=T7,J18<T8,O2>=V5,O2<W5),J18*V7,IF(AND(J18>=T6,J18<T7,O2>=V5,O2<W5),J18*V6,IF(AND(J18>=T9,O2>=U5,O2<V5),J18*U9,IF(AND(J18>=T8,J18<T9,O2>=U5,O2<V5),J18*U8,IF(AND(J18>=T7,J18<T8,O2>=U5,O2<V5),J18*U7,IF(AND(J18>=T6,J18<T7,O2>=U5,O2<V5),J18*U6,"MUY SUAVE EN RETENIDOS 🥱")))))))))))) -> MUY SUAVE EN RETENIDOS 🥱

Sheet 18-09
B2: MENÚ PRINCIPAL | C2: RETENCIÓN | E2: EFECTIVIDAD HOGAR | G2: =GENERAL!B7 -> 1 | I2: EFECTIVIDAD MOVIL | K2: =GENERAL!E7 -> - | M2: EFECTIVIDAD MENSUAL | O2: =GENERAL!K7 -> 1
B4: NÚMERO/ CUENTA | C4: OBSERVACIÓN | D4: GESTIÓN | E4: SERVICIOS RETENIDOS | F4: SERVICIOS CANCELADOS | H4: LLAMADAS | I4: RETENIDOS HOGAR | J4: CAN HOGAR | K4: RETENIDOS MOVIL | L4: CAN MOVIL | M4: INF_NIA | N4: IDENTIDA | O4: GES_NCC | P4: MAL TRANSFER | Q4: LLAMADA CAIDA | T4: RETE | U4: EFEC | V4: EFEC | W4: EFEC | Y4: LISTA | Z4: SERVICIOS | AA4: SERVICIOS
H5: =COUNT(B5:B50) -> 0 | I5: =COUNTIF($D$5:$D$50,"RETENIDO HOGAR") -> 0 | J5: =COUNTIF($D$5:$D$50,"CANCELADO HOGAR") -> 0 | K5: =COUNTIF($D$5:$D$50,"RETENIDO MOVIL") -> 0 | L5: =COUNTIF($D$5:$D$50,"CANCELADO MOVIL") -> 0 | M5: =COUNTIF(D5:D50,"INF_NIA") -> 0 | N5: =COUNTIF(D5:D50,"IDENTIDA") -> 0 | O5: =COUNTIF(D5:D50,"GES_NCC") -> 0 | P5: =COUNTIF($D$5:$D$50,"MAL TRANSFERIDA") -> 0 | Q5: =COUNTIF($D$5:$D$50,"LLAMADA CAIDA") -> 0 | U5: 0.74 | V5: 0.76 | W5: 0.78 | Y5: RETENIDO HOGAR | Z5: 1 | AA5: 1
T6: 17 | U6: 2300 | V6: 2600 | W6: 2900 | Y6: CANCELADO HOGAR | Z6: 2
T7: 19 | U7: 2700 | V7: 3000 | W7: 3300 | Y7: RETENIDO MOVIL | Z7: 3
H8: EFECTIVIDAD DIA HOGAR | K8: EFECTIVIDAD DIA MOVIL | N8: %MARCACIONES | P8: EFECTIVIDAD DIA GENERAL | T8: 21 | U8: 3000 | V8: 3300 | W8: 3600 | Y8: CANCELADO MOVIL
T9: 23 | U9: 3300 | V9: 3600 | W9: 3900 | Y9: INF_NIA
Y10: IDENTIDA
H11: =IFERROR(I5/SUM(I5:J5),"-") -> - | K11: =IFERROR(K5/SUM(K5:L5),"-") -> - | N11: {=IFERROR(SUM(I5:O5/H5),"-")} -> - | P11: =IFERROR(SUM(I5,K5)/SUM(I5:L5),"-") -> - | Y11: GES_NCC
Y12: MAL TRANSFERIDA
Y13: LLAMADA CAIDA
J15: SERVICIOS RETENIDOS | N15: SERVICIOS CANCELADOS
J18: =IFERROR(SUM($E$5:$E$50),"-") -> 0 | N18: =SUM(F5:F50) -> 0
I21: COMISIÓN DEL DÍA
I25: =IF(AND(J18>=T9,O2>=W5),J18*W9,IF(AND(J18>=T8,J18<T9,O2>=W5),J18*W8,IF(AND(J18>=T7,J18<T8,O2>=W5),J18*W7,IF(AND(J18>=T6,J18<T7,O2>=W5),J18*W6,IF(AND(J18>=T9,O2>=V5,O2<W5),J18*V9,IF(AND(J18>=T9,O2>=V5,O2<W5),J18*V8,IF(AND(J18>=T7,J18<T8,O2>=V5,O2<W5),J18*V7,IF(AND(J18>=T6,J18<T7,O2>=V5,O2<W5),J18*V6,IF(AND(J18>=T9,O2>=U5,O2<V5),J18*U9,IF(AND(J18>=T8,J18<T9,O2>=U5,O2<V5),J18*U8,IF(AND(J18>=T7,J18<T8,O2>=U5,O2<V5),J18*U7,IF(AND(J18>=T6,J18<T7,O2>=U5,O2<V5),J18*U6,"MUY SUAVE EN RETENIDOS 🥱")))))))))))) -> MUY SUAVE EN RETENIDOS 🥱

Sheet 19-09
B2: MENÚ PRINCIPAL | C2: RETENCIÓN | E2: EFECTIVIDAD HOGAR | G2: =GENERAL!B7 -> 1 | I2: EFECTIVIDAD MOVIL | K2: =GENERAL!E7 -> - | M2: EFECTIVIDAD MENSUAL | O2: =GENERAL!K7 -> 1
B4: NÚMERO/ CUENTA | C4: OBSERVACIÓN | D4: GESTIÓN | E4: SERVICIOS RETENIDOS | F4: SERVICIOS CANCELADOS | H4: LLAMADAS | I4: RETENIDOS HOGAR | J4: CAN HOGAR | K4: RETENIDOS MOVIL | L4: CAN MOVIL | M4: INF_NIA | N4: IDENTIDA | O4: GES_NCC | P4: MAL TRANSFER | Q4: LLAMADA CAIDA | T4: RETE | U4: EFEC | V4: EFEC | W4: EFEC | Y4: LISTA | Z4: SERVICIOS | AA4: SERVICIOS
H5: =COUNT(B5:B50) -> 0 | I5: =COUNTIF($D$5:$D$50,"RETENIDO HOGAR") -> 0 | J5: =COUNTIF($D$5:$D$50,"CANCELADO HOGAR") -> 0 | K5: =COUNTIF($D$5:$D$50,"RETENIDO MOVIL") -> 0 | L5: =COUNTIF($D$5:$D$50,"CANCELADO MOVIL") -> 0 | M5: =COUNTIF(D5:D50,"INF_NIA") -> 0 | N5: =COUNTIF(D5:D50,"IDENTIDA") -> 0 | O5: =COUNTIF(D5:D50,"GES_NCC") -> 0 | P5: =COUNTIF($D$5:$D$50,"MAL TRANSFERIDA") -> 0 | Q5: =COUNTIF($D$5:$D$50,"LLAMADA CAIDA") -> 0 | U5: 0.74 | V5: 0.76 | W5: 0.78 | Y5: RETENIDO HOGAR | Z5: 1 | AA5: 1
T6: 17 | U6: 2300 | V6: 2600 | W6: 2900 | Y6: CANCELADO HOGAR | Z6: 2
T7: 19 | U7: 2700 | V7: 3000 | W7: 3300 | Y7: RETENIDO MOVIL | Z7: 3
H8: EFECTIVIDAD DIA HOGAR | K8: EFECTIVIDAD DIA MOVIL | N8: %MARCACIONES | P8: EFECTIVIDAD DIA GENERAL | T8: 21 | U8: 3000 | V8: 3300 | W8: 3600 | Y8: CANCELADO MOVIL
T9: 23 | U9: 3300 | V9: 3600 | W9: 3900 | Y9: INF_NIA
Y10: IDENTIDA
H11: =IFERROR(I5/SUM(I5:J5),"-") -> - | K11: =IFERROR(K5/SUM(K5:L5),"-") -> - | N11: {=IFERROR(SUM(I5:O5/H5),"-")} -> - | P11: =IFERROR(SUM(I5,K5)/SUM(I5:L5),"-") -> - | Y11: GES_NCC
Y12: MAL TRANSFERIDA
Y13: LLAMADA CAIDA
J15: SERVICIOS RETENIDOS | N15: SERVICIOS CANCELADOS
J18: =IFERROR(SUM($E$5:$E$50),"-") -> 0 | N18: =SUM(F5:F50) -> 0
I21: COMISIÓN DEL DÍA
I25: =IF(AND(J18>=T9,O2>=W5),J18*W9,IF(AND(J18>=T8,J18<T9,O2>=W5),J18*W8,IF(AND(J18>=T7,J18<T8,O2>=W5),J18*W7,IF(AND(J18>=T6,J18<T7,O2>=W5),J18*W6,IF(AND(J18>=T9,O2>=V5,O2<W5),J18*V9,IF(AND(J18>=T9,O2>=V5,O2<W5),J18*V8,IF(AND(J18>=T7,J18<T8,O2>=V5,O2<W5),J18*V7,IF(AND(J18>=T6,J18<T7,O2>=V5,O2<W5),J18*V6,IF(AND(J18>=T9,O2>=U5,O2<V5),J18*U9,IF(AND(J18>=T8,J18<T9,O2>=U5,O2<V5),J18*U8,IF(AND(J18>=T7,J18<T8,O2>=U5,O2<V5),J18*U7,IF(AND(J18>=T6,J18<T7,O2>=U5,O2<V5),J18*U6,"MUY SUAVE EN RETENIDOS 🥱")))))))))))) -> MUY SUAVE EN RETENIDOS 🥱

Sheet 20-09
B2: MENÚ PRINCIPAL | C2: RETENCIÓN | E2: EFECTIVIDAD HOGAR | G2: =GENERAL!B7 -> 1 | I2: EFECTIVIDAD MOVIL | K2: =GENERAL!E7 -> - | M2: EFECTIVIDAD MENSUAL | O2: =GENERAL!K7 -> 1
B4: NÚMERO/ CUENTA | C4: OBSERVACIÓN | D4: GESTIÓN | E4: SERVICIOS RETENIDOS | F4: SERVICIOS CANCELADOS | H4: LLAMADAS | I4: RETENIDOS HOGAR | J4: CAN HOGAR | K4: RETENIDOS MOVIL | L4: CAN MOVIL | M4: INF_NIA | N4: IDENTIDA | O4: GES_NCC | P4: MAL TRANSFER | Q4: LLAMADA CAIDA | T4: RETE | U4: EFEC | V4: EFEC | W4: EFEC | Y4: LISTA | Z4: SERVICIOS | AA4: SERVICIOS
H5: =COUNT(B5:B50) -> 0 | I5: =COUNTIF($D$5:$D$50,"RETENIDO HOGAR") -> 0 | J5: =COUNTIF($D$5:$D$50,"CANCELADO HOGAR") -> 0 | K5: =COUNTIF($D$5:$D$50,"RETENIDO MOVIL") -> 0 | L5: =COUNTIF($D$5:$D$50,"CANCELADO MOVIL") -> 0 | M5: =COUNTIF(D5:D50,"INF_NIA") -> 0 | N5: =COUNTIF(D5:D50,"IDENTIDA") -> 0 | O5: =COUNTIF(D5:D50,"GES_NCC") -> 0 | P5: =COUNTIF($D$5:$D$50,"MAL TRANSFERIDA") -> 0 | Q5: =COUNTIF($D$5:$D$50,"LLAMADA CAIDA") -> 0 | U5: 0.74 | V5: 0.76 | W5: 0.78 | Y5: RETENIDO HOGAR | Z5: 1 | AA5: 1
T6: 17 | U6: 2300 | V6: 2600 | W6: 2900 | Y6: CANCELADO HOGAR | Z6: 2
T7: 19 | U7: 2700 | V7: 3000 | W7: 3300 | Y7: RETENIDO MOVIL | Z7: 3
H8: EFECTIVIDAD DIA HOGAR | K8: EFECTIVIDAD DIA MOVIL | N8: %MARCACIONES | P8: EFECTIVIDAD DIA GENERAL | T8: 21 | U8: 3000 | V8: 3300 | W8: 3600 | Y8: CANCELADO MOVIL
T9: 23 | U9: 3300 | V9: 3600 | W9: 3900 | Y9: INF_NIA
Y10: IDENTIDA
H11: =IFERROR(I5/SUM(I5:J5),"-") -> - | K11: =IFERROR(K5/SUM(K5:L5),"-") -> - | N11: {=IFERROR(SUM(I5:O5/H5),"-")} -> - | P11: =IFERROR(SUM(I5,K5)/SUM(I5:L5),"-") -> - | Y11: GES_NCC
Y12: MAL TRANSFERIDA
Y13: LLAMADA CAIDA
J15: SERVICIOS RETENIDOS | N15: SERVICIOS CANCELADOS
J18: =IFERROR(SUM($E$5:$E$50),"-") -> 0 | N18: =SUM(F5:F50) -> 0
I21: COMISIÓN DEL DÍA
I25: =IF(AND(J18>=T9,O2>=W5),J18*W9,IF(AND(J18>=T8,J18<T9,O2>=W5),J18*W8,IF(AND(J18>=T7,J18<T8,O2>=W5),J18*W7,IF(AND(J18>=T6,J18<T7,O2>=W5),J18*W6,IF(AND(J18>=T9,O2>=V5,O2<W5),J18*V9,IF(AND(J18>=T9,O2>=V5,O2<W5),J18*V8,IF(AND(J18>=T7,J18<T8,O2>=V5,O2<W5),J18*V7,IF(AND(J18>=T6,J18<T7,O2>=V5,O2<W5),J18*V6,IF(AND(J18>=T9,O2>=U5,O2<V5),J18*U9,IF(AND(J18>=T8,J18<T9,O2>=U5,O2<V5),J18*U8,IF(AND(J18>=T7,J18<T8,O2>=U5,O2<V5),J18*U7,IF(AND(J18>=T6,J18<T7,O2>=U5,O2<V5),J18*U6,"MUY SUAVE EN RETENIDOS 🥱")))))))))))) -> MUY SUAVE EN RETENIDOS 🥱

Sheet 22-09
B2: MENÚ PRINCIPAL | C2: RETENCIÓN | E2: EFECTIVIDAD HOGAR | G2: =GENERAL!B7 -> 1 | I2: EFECTIVIDAD MOVIL | K2: =GENERAL!E7 -> - | M2: EFECTIVIDAD MENSUAL | O2: =GENERAL!K7 -> 1
B4: NÚMERO/ CUENTA | C4: OBSERVACIÓN | D4: GESTIÓN | E4: SERVICIOS RETENIDOS | F4: SERVICIOS CANCELADOS | H4: LLAMADAS | I4: RETENIDOS HOGAR | J4: CAN HOGAR | K4: RETENIDOS MOVIL | L4: CAN MOVIL | M4: INF_NIA | N4: IDENTIDA | O4: GES_NCC | P4: MAL TRANSFER | Q4: LLAMADA CAIDA | T4: RETE | U4: EFEC | V4: EFEC | W4: EFEC | Y4: LISTA | Z4: SERVICIOS | AA4: SERVICIOS
H5: =COUNT(B5:B50) -> 0 | I5: =COUNTIF($D$5:$D$50,"RETENIDO HOGAR") -> 0 | J5: =COUNTIF($D$5:$D$50,"CANCELADO HOGAR") -> 0 | K5: =COUNTIF($D$5:$D$50,"RETENIDO MOVIL") -> 0 | L5: =COUNTIF($D$5:$D$50,"CANCELADO MOVIL") -> 0 | M5: =COUNTIF(D5:D50,"INF_NIA") -> 0 | N5: =COUNTIF(D5:D50,"IDENTIDA") -> 0 | O5: =COUNTIF(D5:D50,"GES_NCC") -> 0 | P5: =COUNTIF($D$5:$D$50,"MAL TRANSFERIDA") -> 0 | Q5: =COUNTIF($D$5:$D$50,"LLAMADA CAIDA") -> 0 | U5: 0.74 | V5: 0.76 | W5: 0.78 | Y5: RETENIDO HOGAR | Z5: 1 | AA5: 1
T6: 17 | U6: 2300 | V6: 2600 | W6: 2900 | Y6: CANCELADO HOGAR | Z6: 2
T7: 19 | U7: 2700 | V7: 3000 | W7: 3300 | Y7: RETENIDO MOVIL | Z7: 3
H8: EFECTIVIDAD DIA HOGAR | K8: EFECTIVIDAD DIA MOVIL | N8: %MARCACIONES | P8: EFECTIVIDAD DIA GENERAL | T8: 21 | U8: 3000 | V8: 3300 | W8: 3600 | Y8: CANCELADO MOVIL
T9: 23 | U9: 3300 | V9: 3600 | W9: 3900 | Y9: INF_NIA
Y10: IDENTIDA
H11: =IFERROR(I5/SUM(I5:J5),"-") -> - | K11: =IFERROR(K5/SUM(K5:L5),"-") -> - | N11: {=IFERROR(SUM(I5:O5/H5),"-")} -> - | P11: =IFERROR(SUM(I5,K5)/SUM(I5:L5),"-") -> - | Y11: GES_NCC
Y12: MAL TRANSFERIDA
Y13: LLAMADA CAIDA
J15: SERVICIOS RETENIDOS | N15: SERVICIOS CANCELADOS
J18: =IFERROR(SUM($E$5:$E$50),"-") -> 0 | N18: =SUM(F5:F50) -> 0
I21: COMISIÓN DEL DÍA
